Workbook

Sheet Cover
B2: TEST CASE
B4: Project Name | C4: OrangeHRM - Recruitment | F4: Creator | G4: Huỳnh Thị Ngọc Trân
B5: Project Code | C5: OHRM-REC | F5: Reviewer/Approver
B6: Document Code | C6: =C5&"_TestCase_V0.1" -> OHRM-REC_TestCase_V0.1 | F6: Issue Date | G6: 46322
F7: Version | G7: 0.1
B10: Record of change
B11: Effective Date | C11: Version | D11: Change Item | E11: *A,D,M | F11: Change description | G11: Reference
B12: 46322 | C12: 0.1 | E12: A | F12: Tạo mới Test Case module TV4 - Recruitment (3 chức năng F10, F11, F12; 98 test case) | G12: OrangeHRM - Test Design (Recruitment)

Sheet Test case List
D1: TEST CASE LIST
B3: Project Name | D3: =Cover!C4 -> OrangeHRM - Recruitment
B4: Project Code | D4: =Cover!C5 -> OHRM-REC
B5: Test Environment Setup Description | D5: Môi trường kiểm thử module Recruitment - OrangeHRM: 1. Website: https://opensource-demo.orangehrmlive.com/web/index.php/auth/login (bản demo công khai, dữ liệu dùng chung và được reset định kỳ) 2. Trình duyệt: Chrome (bản mới nhất) 3. Tài khoản: Admin / admin123 (vai trò Admin) 4. Dữ liệu test: tên vacancy/ứng viên có tiền tố G10 để tránh trùng với người dùng khác; file Resume mẫu (.pdf, .docx, .txt, .exe, .jpg; file 1MB và 2MB) 5. Thứ tự thực hiện: F10 → F11 → F12 (F11 dùng vacancy tạo ở F10, F12 dùng ứng viên tạo ở F11)
B8: No | C8: Function Name | D8: Sheet Name | E8: Description | F8: Pre-Condition
B9: 1 | C9: Quản lý vacancy | D9: F10_Vacancy | E9: Kiểm tra thêm, tìm kiếm/lọc, sửa và xóa vacancy (hợp lệ, không hợp lệ, ngoại lệ) tại Recruitment > Vacancies | F9: Đã đăng nhập OrangeHRM bằng Admin / admin123, đang ở Recruitment > Vacancies
B10: 2 | C10: Thêm và tìm kiếm ứng viên | D10: F11_Candidate | E10: Kiểm tra thêm ứng viên (ràng buộc dữ liệu, tải Resume), tìm kiếm theo các tiêu chí, xem chi tiết và xóa ứng viên | F10: Đã đăng nhập; đã có vacancy (tạo ở F10) để gắn ứng viên; đang ở Recruitment > Candidates
B11: 3 | C11: Cập nhật trạng thái ứng viên | D11: F12_Status | E11: Kiểm tra luồng cập nhật trạng thái (Shortlist, Reject, Interview, Offer, Hire), ràng buộc nhập liệu, workflow, đồng bộ danh sách và lịch sử | F11: Đã đăng nhập; có ứng viên ở trạng thái Application Initiated (tạo ở F11)

Sheet TestDesign
A1: Requirement Level 1 | B1: Requirement Level 2 | C1: Requirement Level 3 | D1: Test Criteria | E1: Test Type | F1: Note
A2: F10. Quản lý vacancy | B2: 10.1. Điều hướng & hiển thị | C2: Điều hướng | D2: Kiểm tra menu [Recruitment] hiển thị và truy cập được | E2: Function
D3: Kiểm tra chuyển sang tab [Vacancies] | E3: Function
C4: Hiển thị | D4: Kiểm tra danh sách vacancy hiển thị đủ các cột và nút [+ Add] | E4: GUI
D5: Kiểm tra bộ lọc hiển thị đủ các trường | E5: GUI
B6: 10.2. Thêm vacancy | C6: Thêm hợp lệ | D6: Kiểm tra thêm vacancy với đầy đủ thông tin hợp lệ | E6: Function
D7: Kiểm tra thêm vacancy chỉ với các trường bắt buộc | E7: Function | F7: Trường bắt buộc: Vacancy Name, Job Title, Hiring Manager
D8: Kiểm tra Number of Positions tại giá trị biên | E8: Function | F8: Boundary; giới hạn theo hệ thống
D9: Kiểm tra Vacancy Name chứa ký tự tiếng Việt có dấu và số | E9: Function
C10: Thêm không hợp lệ | D10: Kiểm tra bỏ trống Vacancy Name | E10: Function | F10: Negative
D11: Kiểm tra bỏ trống Job Title | E11: Function | F11: Negative
D12: Kiểm tra bỏ trống Hiring Manager | E12: Function | F12: Negative
D13: Kiểm tra nhập Hiring Manager không tồn tại | E13: Function | F13: Negative
D14: Kiểm tra Vacancy Name trùng vacancy đã tồn tại | E14: Function | F14: Negative
D15: Kiểm tra Vacancy Name vượt độ dài tối đa (51 ký tự) | E15: Function | F15: Boundary; giới hạn 50 ký tự
D16: Kiểm tra Number of Positions nhập giá trị không hợp lệ | E16: Function | F16: Negative
D17: Kiểm tra Vacancy Name chứa mã script (XSS) | E17: Function | F17: Security; Negative
D18: Kiểm tra nhấn [Cancel] khi đang thêm vacancy | E18: Function
D19: Kiểm tra nhấn [Save] nhiều lần liên tiếp | E19: Function | F19: Exception
B20: 10.3. Tìm kiếm & lọc vacancy | C20: Lọc theo từng tiêu chí | D20: Kiểm tra lọc theo Job Title | E20: Function
D21: Kiểm tra lọc theo Vacancy | E21: Function
D22: Kiểm tra lọc theo Hiring Manager | E22: Function
D23: Kiểm tra lọc theo Status (Active và Closed) | E23: Function
C24: Kết hợp & ngoại lệ | D24: Kiểm tra kết hợp nhiều tiêu chí lọc | E24: Function
D25: Kiểm tra nhấn [Reset] xóa bộ lọc | E25: Function
D26: Kiểm tra lọc không có kết quả | E26: Function | F26: Negative
B27: 10.4. Sửa vacancy | C27: Sửa hợp lệ | D27: Kiểm tra sửa Vacancy Name và Description hợp lệ | E27: Function
D28: Kiểm tra tắt Active, trạng thái vacancy chuyển Closed | E28: Function
C29: Sửa không hợp lệ | D29: Kiểm tra sửa Vacancy Name trùng vacancy khác | E29: Function | F29: Negative
D30: Kiểm tra xóa trống trường bắt buộc khi sửa | E30: Function | F30: Negative
D31: Kiểm tra nhấn [Cancel] khi sửa vacancy | E31: Function
B32: 10.5. Xóa vacancy | C32: Xóa vacancy | D32: Kiểm tra xóa một vacancy và xác nhận xóa | E32: Function
D33: Kiểm tra nhấn [Cancel] ở popup xác nhận xóa | E33: Function
D34: Kiểm tra chọn nhiều vacancy và xóa cùng lúc | E34: Function
D35: Kiểm tra xóa vacancy đang có ứng viên ứng tuyển | E35: Function | F35: Exception; chạy sau khi hoàn thành F11, F12 vì xóa vacancy QA Intern G10 001
A36: F11. Thêm và tìm kiếm ứng viên | B36: 11.1. Hiển thị | C36: Danh sách & form | D36: Kiểm tra danh sách ứng viên hiển thị đủ các cột | E36: GUI
D37: Kiểm tra bộ lọc ứng viên hiển thị đủ các trường | E37: GUI
D38: Kiểm tra form [Add Candidate] hiển thị đủ các trường | E38: GUI
B39: 11.2. Thêm ứng viên | C39: Thêm hợp lệ | D39: Kiểm tra thêm ứng viên với đầy đủ thông tin hợp lệ | E39: Function
D40: Kiểm tra thêm ứng viên chỉ với trường bắt buộc | E40: Function | F40: Trường bắt buộc: First Name, Last Name, Email
...

Sheet F10_Vacancy
A2: Module Code | B2: OHRM_REC_Vacancy | I2: Pass
A3: Test requirement | B3: F10. Quản lý vacancy (TV4 - Recruitment) | I3: Fail
A4: Req ID | B4: F10 | I4: Untested
A5: Tester | B5: Huỳnh Thị Ngọc Trân | I5: Blocked
A6: Pass | B6: Fail | C6: Untested | D6: Blocked | E6: Skipped | F6: Number of Test cases | I6: Skipped
A7: =COUNTIF($F$12:$F$59,"Pass") -> 0 | B7: =COUNTIF($F$12:$F$59,"Fail") -> 1 | C7: =COUNTIF($F$12:$F$59,"Untested") -> 33 | D7: =COUNTIF($F$12:$F$59,"Blocked") -> 0 | E7: =COUNTIF($F$12:$F$59,"Skipped") -> 0 | F7: =COUNTIF($A$12:$A$59,"T-F10-*") -> 34 | I7: Cancel
A9: Test Case ID | B9: Test Case Description | C9: Test Case Procedure | D9: Expected Output | E9: Inter-test case Dependence | F9: Result | G9: Test date | H9: Priority | I9: Note
A10: Chrome - https://opensource-demo.orangehrmlive.com/web/index.php/auth/login
B12: 10.1. Điều hướng & hiển thị
B13: Điều hướng
A14: T-F10-001 | B14: Kiểm tra menu [Recruitment] hiển thị và truy cập được | C14: Tiền điều kiện: Truy cập https://opensource-demo.orangehrmlive.com/web/index.php/auth/login, đăng nhập Admin / admin123. 1. Mở menu bên trái của OrangeHRM. 2. Nhấp vào [Recruitment]. | D14: 1. Menu [Recruitment] hiển thị trong thanh bên trái. 2. Chuyển sang trang Recruitment, tab [Candidates] được mở mặc định. | F14: Untested | G14: 46322 | H14: High
A15: T-F10-002 | B15: Kiểm tra chuyển sang tab [Vacancies] | C15: Tiền điều kiện: Truy cập https://opensource-demo.orangehrmlive.com/web/index.php/auth/login, đăng nhập Admin / admin123. 1. Tại trang Recruitment, nhấp tab [Vacancies]. | D15: Hiển thị trang danh sách Vacancies, URL chứa /recruitment/viewJobVacancy. | E15: T-F10-001 | F15: Untested | G15: 46322 | H15: High
B16: Hiển thị
A17: T-F10-003 | B17: Kiểm tra danh sách vacancy hiển thị đủ các cột và nút [+ Add] | C17: Tiền điều kiện: Truy cập https://opensource-demo.orangehrmlive.com/web/index.php/auth/login, đăng nhập Admin / admin123; đang ở Recruitment > tab Vacancies. 1. Quan sát bảng danh sách tại tab [Vacancies]. | D17: 1. Bảng có các cột: Vacancy, Job Title, Hiring Manager, Status, Actions. 2. Hiển thị dòng "(n) Records Found" khớp số dòng thực tế và nút [+ Add]. | E17: T-F10-002 | F17: Untested | G17: 46322 | H17: Medium
A18: T-F10-004 | B18: Kiểm tra bộ lọc hiển thị đủ các trường | C18: Tiền điều kiện: Truy cập https://opensource-demo.orangehrmlive.com/web/index.php/auth/login, đăng nhập Admin / admin123; đang ở Recruitment > tab Vacancies. 1. Quan sát khu vực bộ lọc phía trên danh sách. | D18: 1. Có các trường: Job Title, Vacancy, Hiring Manager, Status. 2. Có nút [Reset] và [Search]. | E18: T-F10-002 | F18: Untested | G18: 46322 | H18: Medium
B19: 10.2. Thêm vacancy
B20: Thêm hợp lệ
A21: T-F10-005 | B21: Kiểm tra thêm vacancy với đầy đủ thông tin hợp lệ | C21: Tiền điều kiện: Truy cập https://opensource-demo.orangehrmlive.com/web/index.php/auth/login, đăng nhập Admin / admin123; đang ở Recruitment > tab Vacancies. 1. Nhấp [+ Add]. 2. Nhập Vacancy Name = "QA Intern G10 001" 3. Chọn Job Title = "QA Engineer" 4. Nhập Description = "Tuyển thực tập sinh kiểm thử" 5. Nhập Hiring Manager = "a" và chọn một gợi ý. 6. Nhập Number of Positions = 3, bật Active và Publish in RSS Feed and Web Page. 7. Nhấp [Save]. | D21: 1. Hiển thị thông báo "Successfully Saved" 2. Chuyển sang trang Edit Vacancy, các trường hiển thị đúng dữ liệu vừa nhập. 3. Vacancy mới xuất hiện trong danh sách với Status = Active. | E21: T-F10-002 | F21: Untested | G21: 46322 | H21: High
A22: T-F10-006 | B22: Kiểm tra thêm vacancy chỉ với các trường bắt buộc | C22: Tiền điều kiện: Truy cập https://opensource-demo.orangehrmlive.com/web/index.php/auth/login, đăng nhập Admin / admin123; đang ở Recruitment > tab Vacancies. 1. Nhấp [+ Add]. 2. Nhập Vacancy Name = "QA Intern G10 002" 3. Chọn Job Title = "QA Engineer" 4. Chọn một Hiring Manager từ gợi ý. 5. Nhấp [Save]. | D22: Hiển thị "Successfully Saved" và tạo vacancy thành công. | E22: T-F10-002 | F22: Untested | G22: 46322 | H22: High | I22: Trường bắt buộc: Vacancy Name, Job Title, Hiring Manager
A23: T-F10-007 | B23: Kiểm tra Number of Positions tại giá trị biên | C23: Tiền điều kiện: Truy cập https://opensource-demo.orangehrmlive.com/web/index.php/auth/login, đăng nhập Admin / admin123; đang ở Recruitment > tab Vacancies. 1. Thêm vacancy "QA Intern G10 P1" với Number of Positions = 1 (các trường khác hợp lệ) 2. Thêm vacancy "QA Intern G10 P99" với Number of Positions = 99. | D23: Cả hai vacancy được lưu thành công với số lượng đúng (dùng lại cho TC xóa nhiều vacancy) | E23: T-F10-002 | F23: Untested | G23: 46322 | H23: Medium | I23: Boundary; giới hạn theo hệ thống
A24: T-F10-008 | B24: Kiểm tra Vacancy Name chứa ký tự tiếng Việt có dấu và số | C24: Tiền điều kiện: Truy cập https://opensource-demo.orangehrmlive.com/web/index.php/auth/login, đăng nhập Admin / admin123; đang ở Recruitment > tab Vacancies. 1. Nhập Vacancy Name = "Chuyên viên tuyển dụng 2026" 2. Nhập các trường bắt buộc còn lại hợp lệ. 3. Nhấp [Save]. | D24: Lưu thành công, tên hiển thị đúng dấu tiếng Việt trong danh sách. | E24: T-F10-002 | F24: Untested | G24: 46322 | H24: Medium
B25: Thêm không hợp lệ
A26: T-F10-009 | B26: Kiểm tra bỏ trống Vacancy Name | C26: Tiền điều kiện: Truy cập https://opensource-demo.orangehrmlive.com/web/index.php/auth/login, đăng nhập Admin / admin123; đang ở Recruitment > tab Vacancies. 1. Nhấp [+ Add]. 2. Để trống Vacancy Name, nhập các trường bắt buộc khác hợp lệ. 3. Nhấp [Save]. | D26: 1. Hiển thị lỗi "Required" dưới trường Vacancy Name. 2. Không tạo vacancy. | E26: T-F10-002 | F26: Untested | G26: 46322 | H26: High | I26: Negative
A27: T-F10-010 | B27: Kiểm tra bỏ trống Job Title | C27: Tiền điều kiện: Truy cập https://opensource-demo.orangehrmlive.com/web/index.php/auth/login, đăng nhập Admin / admin123; đang ở Recruitment > tab Vacancies. 1. Nhấp [+ Add]. 2. Nhập Vacancy Name hợp lệ, để trống Job Title. 3. Nhấp [Save]. | D27: 1. Hiển thị lỗi "Required" dưới trường Job Title. 2. Không tạo vacancy. | E27: T-F10-002 | F27: Untested | G27: 46322 | H27: High | I27: Negative
A28: T-F10-011 | B28: Kiểm tra bỏ trống Hiring Manager | C28: Tiền điều kiện: Truy cập https://opensource-demo.orangehrmlive.com/web/index.php/auth/login, đăng nhập Admin / admin123; đang ở Recruitment > tab Vacancies. 1. Nhấp [+ Add]. 2. Nhập Vacancy Name, Job Title hợp lệ, để trống Hiring Manager. 3. Nhấp [Save]. | D28: 1. Hiển thị lỗi "Required" dưới trường Hiring Manager. 2. Không tạo vacancy. | E28: T-F10-002 | F28: Untested | G28: 46322 | H28: High | I28: Negative
A29: T-F10-012 | B29: Kiểm tra nhập Hiring Manager không tồn tại | C29: Tiền điều kiện: Truy cập https://opensource-demo.orangehrmlive.com/web/index.php/auth/login, đăng nhập Admin / admin123; đang ở Recruitment > tab Vacancies. 1. Nhấp [+ Add]. 2. Nhập Hiring Manager = "zzzzqqq" (không chọn gợi ý) 3. Nhập các trường khác hợp lệ, nhấp [Save]. | D29: 1. Hiển thị lỗi "Invalid" tại trường Hiring Manager. 2. Không tạo vacancy. | E29: T-F10-002 | F29: Untested | G29: 46322 | H29: Medium | I29: Negative
A30: T-F10-013 | B30: Kiểm tra Vacancy Name trùng vacancy đã tồn tại | C30: Tiền điều kiện: Truy cập https://opensource-demo.orangehrmlive.com/web/index.php/auth/login, đăng nhập Admin / admin123; đang ở Recruitment > tab Vacancies. 1. Nhấp [+ Add]. 2. Nhập Vacancy Name = "QA Intern G10 001" (đã tồn tại), các trường khác hợp lệ. 3. Nhấp [Save]. | D30: 1. Hiển thị lỗi "Already exists" tại trường Vacancy Name. 2. Không tạo vacancy trùng. | E30: T-F10-005 | F30: Untested | G30: 46322 | H30: High | I30: Negative
A31: T-F10-014 | B31: Kiểm tra Vacancy Name vượt độ dài tối đa (51 ký tự) | C31: Tiền điều kiện: Truy cập https://opensource-demo.orangehrmlive.com/web/index.php/auth/login, đăng nhập Admin / admin123; đang ở Recruitment > tab Vacancies. 1. Nhấp [+ Add]. 2. Nhập Vacancy Name gồm 51 ký tự. 3. Nhập các trường khác hợp lệ, nhấp [Save]. | D31: 1. Hiển thị lỗi "Should not exceed 50 characters" 2. Không tạo vacancy. | E31: T-F10-002 | F31: Untested | G31: 46322 | H31: Medium | I31: Boundary; giới hạn 50 ký tự
A32: T-F10-015 | B32: Kiểm tra Number of Positions nhập giá trị không hợp lệ | C32: Tiền điều kiện: Truy cập https://opensource-demo.orangehrmlive.com/web/index.php/auth/login, đăng nhập Admin / admin123; đang ở Recruitment > tab Vacancies. 1. Nhấp [+ Add], nhập các trường bắt buộc hợp lệ. 2. Nhập Number of Positions = "abc", nhấp [Save]. 3. Nhập Number of Positions = "-1", nhấp [Save]. | D32: 1. Hiển thị lỗi định dạng số tại Number of Positions ở cả hai trường hợp. 2. Không tạo vacancy. | E32: T-F10-002 | F32: Untested | G32: 46322 | H32: Medium | I32: Negative
A33: T-F10-016 | B33: Kiểm tra Vacancy Name chứa mã script (XSS) | C33: Tiền điều kiện: Truy cập https://opensource-demo.orangehrmlive.com/web/index.php/auth/login, đăng nhập Admin / admin123; đang ở Recruitment > tab Vacancies. 1. Nhấp [+ Add]. 2. Nhập Vacancy Name = "<script>alert('XSS')</script>" 3. Nhập các trường khác hợp lệ, nhấp [Save]. | D33: 1. Script không được thực thi (không hiện hộp thoại alert) 2. Tên hiển thị dạng văn bản thường hoặc bị từ chối. | E33: T-F10-002 | F33: Untested | G33: 46322 | H33: High | I33: Security; Negative
A34: T-F10-017 | B34: Kiểm tra nhấn [Cancel] khi đang thêm vacancy | C34: Tiền điều kiện: Truy cập https://opensource-demo.orangehrmlive.com/web/index.php/auth/login, đăng nhập Admin / admin123; đang ở Recruitment > tab Vacancies. 1. Nhấp [+ Add], nhập một số thông tin. 2. Nhấp [Cancel]. | D34: 1. Quay về danh sách Vacancies. 2. Không có vacancy mới được tạo. | E34: T-F10-002 | F34: Untested | G34: 46322 | H34: Medium
A35: T-F10-018 | B35: Kiểm tra nhấn [Save] nhiều lần liên tiếp | C35: Tiền điều kiện: Truy cập https://opensource-demo.orangehrmlive.com/web/index.php/auth/login, đăng nhập Admin / admin123; đang ở Recruitment > tab Vacancies. 1. Nhấp [+ Add], nhập dữ liệu hợp lệ (Vacancy Name = "QA Intern G10 003") 2. Nhấp nhanh [Save] 3 lần liên tiếp. | D35: Chỉ tạo 1 vacancy, không xuất hiện bản ghi trùng hoặc lỗi hệ thống. | E35: T-F10-002 | F35: Untested | G35: 46322 | H35: Medium | I35: Exception
B36: 10.3. Tìm kiếm & lọc vacancy
B37: Lọc theo từng tiêu chí
A38: T-F10-019 | B38: Kiểm tra lọc theo Job Title | C38: Tiền điều kiện: Truy cập https://opensource-demo.orangehrmlive.com/web/index.php/auth/login, đăng nhập Admin / admin123; đang ở Recruitment > tab Vacancies. 1. Chọn Job Title = "QA Engineer" 2. Nhấp [Search]. | D38: 1. Chỉ hiển thị vacancy có Job Title = QA Engineer. 2. Số "Records Found" cập nhật đúng. | E38: T-F10-002 | F38: Untested | G38: 46322 | H38: High
A39: T-F10-020 | B39: Kiểm tra lọc theo Vacancy | C39: Tiền điều kiện: Truy cập https://opensource-demo.orangehrmlive.com/web/index.php/auth/login, đăng nhập Admin / admin123; đang ở Recruitment > tab Vacancies. 1. Chọn Vacancy = "QA Intern G10 001" trong dropdown. 2. Nhấp [Search]. | D39: Chỉ hiển thị đúng vacancy đã chọn. | E39: T-F10-005 | F39: Untested | G39: 46322 | H39: High
A40: T-F10-021 | B40: Kiểm tra lọc theo Hiring Manager | C40: Tiền điều kiện: Truy cập https://opensource-demo.orangehrmlive.com/web/index.php/auth/login, đăng nhập Admin / admin123; đang ở Recruitment > tab Vacancies. 1. Chọn một Hiring Manager trong dropdown. 2. Nhấp [Search]. | D40: Chỉ hiển thị vacancy thuộc Hiring Manager đã chọn. | E40: T-F10-002 | F40: Untested | G40: 46322 | H40: Medium
A41: T-F10-022 | B41: Kiểm tra lọc theo Status (Active và Closed) | C41: Tiền điều kiện: Truy cập https://opensource-demo.orangehrmlive.com/web/index.php/auth/login, đăng nhập Admin / admin123; đang ở Recruitment > tab Vacancies. 1. Chọn Status = "Active", nhấp [Search]. 2. Chọn Status = "Closed", nhấp [Search]. | D41: 1. Lần 1: chỉ hiển thị vacancy Active. 2. Lần 2: chỉ hiển thị vacancy Closed. | E41: T-F10-002 | F41: Untested | G41: 46322 | H41: Medium
B42: Kết hợp & ngoại lệ
A43: T-F10-023 | B43: Kiểm tra kết hợp nhiều tiêu chí lọc | C43: Tiền điều kiện: Truy cập https://opensource-demo.orangehrmlive.com/web/index.php/auth/login, đăng nhập Admin / admin123; đang ở Recruitment > tab Vacancies. 1. Chọn Job Title = "QA Engineer" và Status = "Active" 2. Nhấp [Search]. | D43: Danh sách thỏa đồng thời tất cả điều kiện lọc. | E43: T-F10-002 | F43: Untested | G43: 46322 | H43: Medium
...

Sheet F11_Candidate
A2: Module Code | B2: OHRM_REC_Candidate | I2: Pass
A3: Test requirement | B3: F11. Thêm và tìm kiếm ứng viên (TV4 - Recruitment) | I3: Fail
A4: Req ID | B4: F11 | I4: Untested
A5: Tester | B5: Huỳnh Thị Ngọc Trân | I5: Blocked
A6: Pass | B6: Fail | C6: Untested | D6: Blocked | E6: Skipped | F6: Number of Test cases | I6: Skipped
A7: =COUNTIF($F$12:$F$57,"Pass") -> 7 | B7: =COUNTIF($F$12:$F$57,"Fail") -> 1 | C7: =COUNTIF($F$12:$F$57,"Untested") -> 28 | D7: =COUNTIF($F$12:$F$57,"Blocked") -> 0 | E7: =COUNTIF($F$12:$F$57,"Skipped") -> 0 | F7: =COUNTIF($A$12:$A$57,"T-F11-*") -> 36 | I7: Cancel
A9: Test Case ID | B9: Test Case Description | C9: Test Case Procedure | D9: Expected Output | E9: Inter-test case Dependence | F9: Result | G9: Test date | H9: Priority | I9: Note
A10: Chrome - https://opensource-demo.orangehrmlive.com/web/index.php/auth/login
B12: 11.1. Hiển thị
B13: Danh sách & form
A14: T-F11-001 | B14: Kiểm tra danh sách ứng viên hiển thị đủ các cột | C14: Tiền điều kiện: Truy cập https://opensource-demo.orangehrmlive.com/web/index.php/auth/login, đăng nhập Admin / admin123. 1. Vào Recruitment > tab [Candidates]. | D14: 1. Bảng có các cột: Vacancy, Candidate, Hiring Manager, Date of Application, Status, Actions. 2. Hiển thị dòng "(n) Records Found" | F14: Untested | G14: 46322 | H14: Medium
A15: T-F11-002 | B15: Kiểm tra bộ lọc ứng viên hiển thị đủ các trường | C15: Tiền điều kiện: Truy cập https://opensource-demo.orangehrmlive.com/web/index.php/auth/login, đăng nhập Admin / admin123; đang ở Recruitment > tab Candidates. 1. Quan sát khu vực bộ lọc tại tab [Candidates]. | D15: 1. Có: Job Title, Vacancy, Hiring Manager, Status, Candidate Name, Keywords, Date of Application (From/To), Methods of Application. 2. Có nút [Reset], [Search]. | E15: T-F11-001 | F15: Untested | G15: 46322 | H15: Medium
A16: T-F11-003 | B16: Kiểm tra form [Add Candidate] hiển thị đủ các trường | C16: Tiền điều kiện: Truy cập https://opensource-demo.orangehrmlive.com/web/index.php/auth/login, đăng nhập Admin / admin123; đang ở Recruitment > tab Candidates. 1. Nhấp [+ Add]. | D16: 1. Có: Full Name (First/Middle/Last), Vacancy, Email, Contact Number, Resume (Browse), Keywords, Date of Application, Notes, Consent to keep data. 2. Có nút [Cancel], [Save]. | E16: T-F11-001 | F16: Untested | G16: 46322 | H16: Medium
B17: 11.2. Thêm ứng viên
B18: Thêm hợp lệ
A19: T-F11-004 | B19: Kiểm tra thêm ứng viên với đầy đủ thông tin hợp lệ | C19: Tiền điều kiện: Truy cập https://opensource-demo.orangehrmlive.com/web/index.php/auth/login, đăng nhập Admin / admin123; đang ở Recruitment > tab Candidates. 1. Nhấp [+ Add]. 2. Nhập First Name = "An", Middle Name = "Văn", Last Name = "Nguyễn" 3. Chọn Vacancy = "QA Intern G10 001" 4. Nhập Email = "an.nguyen@example.com", Contact Number = "0901234567" 5. Tải lên Resume "cv_an.pdf" (dưới 1MB) 6. Nhập Keywords = "selenium, java", Date of Application = ngày hiện tại, Notes = "Ứng viên test" 7. Tích Consent to keep data, nhấp [Save]. | D19: 1. Hiển thị "Successfully Saved" 2. Chuyển sang trang chi tiết ứng viên với Status = "Application Initiated" 3. Thông tin hiển thị đúng như đã nhập. | E19: T-F11-001 | F19: Untested | G19: 46322 | H19: High
A20: T-F11-005 | B20: Kiểm tra thêm ứng viên chỉ với trường bắt buộc | C20: Tiền điều kiện: Truy cập https://opensource-demo.orangehrmlive.com/web/index.php/auth/login, đăng nhập Admin / admin123; đang ở Recruitment > tab Candidates. 1. Nhấp [+ Add]. 2. Nhập First Name = "Bình", Last Name = "Trần", Email = "binh.tran@example.com" 3. Nhấp [Save]. | D20: Hiển thị "Successfully Saved" và tạo ứng viên thành công. | E20: T-F11-001 | F20: Untested | G20: 46322 | H20: High | I20: Trường bắt buộc: First Name, Last Name, Email
A21: T-F11-006 | B21: Kiểm tra thêm ứng viên gắn với vacancy đã chọn | C21: Tiền điều kiện: Truy cập https://opensource-demo.orangehrmlive.com/web/index.php/auth/login, đăng nhập Admin / admin123; đang ở Recruitment > tab Candidates. 1. Nhấp [+ Add], nhập thông tin bắt buộc hợp lệ. 2. Chọn Vacancy = "QA Intern G10 001" 3. Nhấp [Save]. 4. Vào danh sách Candidates. | D21: Ứng viên hiển thị với cột Vacancy = QA Intern G10 001 và Hiring Manager tương ứng. | E21: T-F10-006 | F21: Untested | G21: 46322 | H21: High
A22: T-F11-007 | B22: Kiểm tra tải lên Resume đúng định dạng cho phép | C22: Tiền điều kiện: Truy cập https://opensource-demo.orangehrmlive.com/web/index.php/auth/login, đăng nhập Admin / admin123; đang ở Recruitment > tab Candidates. 1. Thêm ứng viên hợp lệ, tải lên Resume "cv.docx" 2. Lặp lại với "cv.txt" | D22: Cả hai file được tải lên thành công, lưu ứng viên thành công. | E22: T-F11-001 | F22: Untested | G22: 46322 | H22: Medium | I22: Định dạng: docx, doc, odt, pdf, rtf, txt
A23: T-F11-008 | B23: Kiểm tra tải lên Resume có dung lượng đúng 1MB | C23: Tiền điều kiện: Truy cập https://opensource-demo.orangehrmlive.com/web/index.php/auth/login, đăng nhập Admin / admin123; đang ở Recruitment > tab Candidates. 1. Thêm ứng viên hợp lệ. 2. Tải lên Resume .pdf dung lượng đúng 1MB. 3. Nhấp [Save]. | D23: Tải lên và lưu thành công, không báo lỗi dung lượng. | E23: T-F11-001 | F23: Untested | G23: 46322 | H23: Medium | I23: Boundary; giới hạn 1MB
A24: T-F11-009 | B24: Kiểm tra thêm ứng viên có tên tiếng Việt có dấu | C24: Tiền điều kiện: Truy cập https://opensource-demo.orangehrmlive.com/web/index.php/auth/login, đăng nhập Admin / admin123; đang ở Recruitment > tab Candidates. 1. Nhập First Name = "Thị", Last Name = "Nguyễn Hoàng", Email hợp lệ. 2. Nhấp [Save]. | D24: Lưu thành công, tên hiển thị đúng dấu trong danh sách. | E24: T-F11-001 | F24: Untested | G24: 46322 | H24: Medium
B25: Thêm không hợp lệ
A26: T-F11-010 | B26: Kiểm tra bỏ trống First Name | C26: Tiền điều kiện: Truy cập https://opensource-demo.orangehrmlive.com/web/index.php/auth/login, đăng nhập Admin / admin123; đang ở Recruitment > tab Candidates. 1. Nhấp [+ Add]. 2. Để trống First Name, nhập Last Name và Email hợp lệ. 3. Nhấp [Save]. | D26: 1. Hiển thị lỗi "Required" dưới trường First Name. 2. Không tạo ứng viên. | E26: T-F11-001 | F26: Untested | G26: 46322 | H26: High | I26: Negative
A27: T-F11-011 | B27: Kiểm tra bỏ trống Last Name | C27: Tiền điều kiện: Truy cập https://opensource-demo.orangehrmlive.com/web/index.php/auth/login, đăng nhập Admin / admin123; đang ở Recruitment > tab Candidates. 1. Nhấp [+ Add]. 2. Để trống Last Name, nhập First Name và Email hợp lệ. 3. Nhấp [Save]. | D27: 1. Hiển thị lỗi "Required" dưới trường Last Name. 2. Không tạo ứng viên. | E27: T-F11-001 | F27: Untested | G27: 46322 | H27: High | I27: Negative
A28: T-F11-012 | B28: Kiểm tra bỏ trống Email | C28: Tiền điều kiện: Truy cập https://opensource-demo.orangehrmlive.com/web/index.php/auth/login, đăng nhập Admin / admin123; đang ở Recruitment > tab Candidates. 1. Nhấp [+ Add]. 2. Nhập First Name, Last Name, để trống Email. 3. Nhấp [Save]. | D28: 1. Hiển thị lỗi "Required" dưới trường Email. 2. Không tạo ứng viên. | E28: T-F11-001 | F28: Untested | G28: 46322 | H28: High | I28: Negative
A29: T-F11-013 | B29: Kiểm tra nhập Email sai định dạng | C29: Tiền điều kiện: Truy cập https://opensource-demo.orangehrmlive.com/web/index.php/auth/login, đăng nhập Admin / admin123; đang ở Recruitment > tab Candidates. 1. Nhấp [+ Add], nhập First Name, Last Name hợp lệ. 2. Nhập Email = "abc@", nhấp [Save]. 3. Nhập Email = "abc.com", nhấp [Save]. | D29: 1. Hiển thị lỗi "Expected format: admin@example.com" ở cả hai trường hợp. 2. Không tạo ứng viên. | E29: T-F11-001 | F29: Untested | G29: 46322 | H29: High | I29: Negative
A30: T-F11-014 | B30: Kiểm tra nhập Contact Number chứa chữ cái | C30: Tiền điều kiện: Truy cập https://opensource-demo.orangehrmlive.com/web/index.php/auth/login, đăng nhập Admin / admin123; đang ở Recruitment > tab Candidates. 1. Nhấp [+ Add], nhập thông tin bắt buộc hợp lệ. 2. Nhập Contact Number = "abc123" 3. Nhấp [Save]. | D30: 1. Hiển thị lỗi định dạng số điện thoại (chỉ cho phép số và + - / ( )) 2. Không tạo ứng viên. | E30: T-F11-001 | F30: Untested | G30: 46322 | H30: Medium | I30: Negative
A31: T-F11-015 | B31: Kiểm tra First Name vượt độ dài tối đa (31 ký tự) | C31: Tiền điều kiện: Truy cập https://opensource-demo.orangehrmlive.com/web/index.php/auth/login, đăng nhập Admin / admin123; đang ở Recruitment > tab Candidates. 1. Nhấp [+ Add]. 2. Nhập First Name gồm 31 ký tự, các trường bắt buộc khác hợp lệ. 3. Nhấp [Save]. | D31: 1. Hiển thị lỗi "Should not exceed 30 characters" 2. Không tạo ứng viên. | E31: T-F11-001 | F31: Untested | G31: 46322 | H31: Medium | I31: Boundary; giới hạn 30 ký tự
A32: T-F11-016 | B32: Kiểm tra tải lên Resume sai định dạng | C32: Tiền điều kiện: Truy cập https://opensource-demo.orangehrmlive.com/web/index.php/auth/login, đăng nhập Admin / admin123; đang ở Recruitment > tab Candidates. 1. Nhấp [+ Add], nhập thông tin bắt buộc hợp lệ. 2. Tải lên file "test.exe" hoặc "anh.jpg" | D32: 1. Hiển thị lỗi "File type not allowed" 2. File không được chấp nhận. | E32: T-F11-001 | F32: Untested | G32: 46322 | H32: High | I32: Negative
A33: T-F11-017 | B33: Kiểm tra tải lên Resume vượt dung lượng tối đa | C33: Tiền điều kiện: Truy cập https://opensource-demo.orangehrmlive.com/web/index.php/auth/login, đăng nhập Admin / admin123; đang ở Recruitment > tab Candidates. 1. Nhấp [+ Add], nhập thông tin bắt buộc hợp lệ. 2. Tải lên file .pdf dung lượng 2MB. | D33: 1. Hiển thị lỗi "Attachment Size Exceeded" 2. File không được chấp nhận. | E33: T-F11-001 | F33: Untested | G33: 46322 | H33: High | I33: Negative; Boundary
A34: T-F11-018 | B34: Kiểm tra nhập Date of Application sai định dạng | C34: Tiền điều kiện: Truy cập https://opensource-demo.orangehrmlive.com/web/index.php/auth/login, đăng nhập Admin / admin123; đang ở Recruitment > tab Candidates. 1. Nhấp [+ Add], nhập thông tin bắt buộc hợp lệ. 2. Nhập Date of Application = "abc" 3. Nhấp [Save]. | D34: 1. Hiển thị lỗi định dạng ngày hợp lệ. 2. Không tạo ứng viên. | E34: T-F11-001 | F34: Untested | G34: 46322 | H34: Medium | I34: Negative
A35: T-F11-019 | B35: Kiểm tra nhập mã script vào Keywords và Notes (XSS) | C35: Tiền điều kiện: Truy cập https://opensource-demo.orangehrmlive.com/web/index.php/auth/login, đăng nhập Admin / admin123; đang ở Recruitment > tab Candidates. 1. Nhấp [+ Add], nhập thông tin bắt buộc hợp lệ. 2. Nhập Keywords = "<script>alert(1)</script>", Notes tương tự. 3. Nhấp [Save], mở chi tiết ứng viên. | D35: Script không được thực thi, nội dung hiển thị dạng văn bản. | E35: T-F11-001 | F35: Untested | G35: 46322 | H35: High | I35: Security; Negative
A36: T-F11-020 | B36: Kiểm tra nhấn [Cancel] khi đang thêm ứng viên | C36: Tiền điều kiện: Truy cập https://opensource-demo.orangehrmlive.com/web/index.php/auth/login, đăng nhập Admin / admin123; đang ở Recruitment > tab Candidates. 1. Nhấp [+ Add], nhập một số thông tin. 2. Nhấp [Cancel]. | D36: 1. Quay về danh sách Candidates. 2. Không có ứng viên mới được tạo. | E36: T-F11-001 | F36: Untested | G36: 46322 | H36: Medium
A37: T-F11-021 | B37: Kiểm tra nhấn [Save] nhiều lần liên tiếp | C37: Tiền điều kiện: Truy cập https://opensource-demo.orangehrmlive.com/web/index.php/auth/login, đăng nhập Admin / admin123; đang ở Recruitment > tab Candidates. 1. Nhập thông tin hợp lệ (First Name = "Dũng", Last Name = "Lê") 2. Nhấp nhanh [Save] 3 lần liên tiếp. | D37: Chỉ tạo 1 ứng viên, không có bản ghi trùng hoặc lỗi hệ thống. | E37: T-F11-001 | F37: Untested | G37: 46322 | H37: Medium | I37: Exception
B38: 11.3. Tìm kiếm ứng viên
B39: Tìm theo từng tiêu chí
A40: T-F11-022 | B40: Kiểm tra tìm theo Candidate Name (chọn gợi ý) | C40: Tiền điều kiện: Truy cập https://opensource-demo.orangehrmlive.com/web/index.php/auth/login, đăng nhập Admin / admin123; đang ở Recruitment > tab Candidates. 1. Nhập "An" vào ô Candidate Name. 2. Chọn "An Văn Nguyễn" trong danh sách gợi ý. 3. Nhấp [Search]. | D40: Chỉ hiển thị ứng viên được chọn. | E40: T-F11-004 | F40: Untested | G40: 46322 | H40: High
A41: T-F11-023 | B41: Kiểm tra Candidate Name nhập tên không tồn tại | C41: Tiền điều kiện: Truy cập https://opensource-demo.orangehrmlive.com/web/index.php/auth/login, đăng nhập Admin / admin123; đang ở Recruitment > tab Candidates. 1. Nhập "zzzzqqq" vào ô Candidate Name (không chọn gợi ý) 2. Nhấp [Search]. | D41: 1. Hiển thị lỗi "Invalid" hoặc "No Records Found" theo hệ thống. 2. Không lỗi hệ thống. | E41: T-F11-001 | F41: Untested | G41: 46322 | H41: Medium | I41: Negative
A42: T-F11-024 | B42: Kiểm tra lọc theo Job Title | C42: Tiền điều kiện: Truy cập https://opensource-demo.orangehrmlive.com/web/index.php/auth/login, đăng nhập Admin / admin123; đang ở Recruitment > tab Candidates. 1. Chọn Job Title = "QA Engineer" 2. Nhấp [Search]. | D42: Chỉ hiển thị ứng viên của vacancy thuộc Job Title đã chọn. | E42: T-F11-001 | F42: Untested | G42: 46322 | H42: Medium
A43: T-F11-025 | B43: Kiểm tra lọc theo Vacancy | C43: Tiền điều kiện: Truy cập https://opensource-demo.orangehrmlive.com/web/index.php/auth/login, đăng nhập Admin / admin123; đang ở Recruitment > tab Candidates. 1. Chọn Vacancy = "QA Intern G10 001" 2. Nhấp [Search]. | D43: Chỉ hiển thị ứng viên của vacancy đã chọn. | E43: T-F11-006 | F43: Untested | G43: 46322 | H43: High
...

Sheet F12_Status
A2: Module Code | B2: OHRM_REC_Status | I2: Pass
A3: Test requirement | B3: F12. Cập nhật trạng thái ứng viên (TV4 - Recruitment) | I3: Fail
A4: Req ID | B4: F12 | I4: Untested
A5: Tester | B5: Huỳnh Thị Ngọc Trân | I5: Blocked
A6: Pass | B6: Fail | C6: Untested | D6: Blocked | E6: Skipped | F6: Number of Test cases | I6: Skipped
A7: =COUNTIF($F$12:$F$50,"Pass") -> 23 | B7: =COUNTIF($F$12:$F$50,"Fail") -> 5 | C7: =COUNTIF($F$12:$F$50,"Untested") -> 0 | D7: =COUNTIF($F$12:$F$50,"Blocked") -> 0 | E7: =COUNTIF($F$12:$F$50,"Skipped") -> 0 | F7: =COUNTIF($A$12:$A$50,"T-F12-*") -> 28 | I7: Cancel
A9: Test Case ID | B9: Test Case Description | C9: Test Case Procedure | D9: Expected Output | E9: Inter-test case Dependence | F9: Result | G9: Test date | H9: Priority | I9: Note
A10: Chrome - https://opensource-demo.orangehrmlive.com/web/index.php/auth/login
B12: 12.1. Hiển thị
B13: Application Stage
A14: T-F12-001 | B14: Kiểm tra trạng thái ban đầu và các nút thao tác của ứng viên mới | C14: Tiền điều kiện: Truy cập https://opensource-demo.orangehrmlive.com/web/index.php/auth/login, đăng nhập Admin / admin123; đã có ứng viên mới tạo (theo T-F11-005, mỗi test dùng 1 ứng viên riêng) ở đúng trạng thái đầu vào của test, đang ở trang chi tiết ứng viên. 1. Mở trang chi tiết ứng viên vừa tạo (T-F11-005) | D14: 1. Phần Application Stage hiển thị Status = "Application Initiated" 2. Hiển thị nút [Reject] và [Shortlist]. | E14: T-F11-005 | F14: Pass | G14: 46322 | H14: High
A15: T-F12-002 | B15: Kiểm tra thông tin ứng viên hiển thị đúng ở trang chi tiết | C15: Tiền điều kiện: Truy cập https://opensource-demo.orangehrmlive.com/web/index.php/auth/login, đăng nhập Admin / admin123; đã có ứng viên mới tạo (theo T-F11-005, mỗi test dùng 1 ứng viên riêng) ở đúng trạng thái đầu vào của test, đang ở trang chi tiết ứng viên. 1. Quan sát thông tin ứng viên (tên, vacancy, email, ngày nộp hồ sơ) | D15: Thông tin hiển thị đúng như khi thêm ứng viên. | E15: T-F12-001 | F15: Pass | G15: 46322 | H15: Medium
B16: 12.2. Cập nhật trạng thái hợp lệ
B17: Shortlist / Reject
A18: T-F12-003 | B18: Kiểm tra Shortlist ứng viên kèm ghi chú | C18: Tiền điều kiện: Truy cập https://opensource-demo.orangehrmlive.com/web/index.php/auth/login, đăng nhập Admin / admin123; đã có ứng viên mới tạo (theo T-F11-005, mỗi test dùng 1 ứng viên riêng) ở đúng trạng thái đầu vào của test, đang ở trang chi tiết ứng viên. 1. Nhấp [Shortlist]. 2. Nhập Notes = "Hồ sơ phù hợp" 3. Nhấp [Save]. | D18: 1. Hiển thị "Successfully Saved" 2. Status chuyển "Shortlisted" 3. Hiển thị các nút [Reject] và [Schedule Interview]. | E18: T-F12-001 | F18: Pass | G18: 46322 | H18: High
A19: T-F12-004 | B19: Kiểm tra Shortlist ứng viên không nhập ghi chú | C19: Tiền điều kiện: Truy cập https://opensource-demo.orangehrmlive.com/web/index.php/auth/login, đăng nhập Admin / admin123; đã có ứng viên mới tạo (theo T-F11-005, mỗi test dùng 1 ứng viên riêng) ở đúng trạng thái đầu vào của test, đang ở trang chi tiết ứng viên. 1. Nhấp [Shortlist]. 2. Để trống Notes, nhấp [Save]. | D19: Lưu thành công, Status = "Shortlisted" | E19: T-F12-001 | F19: Pass | G19: 46322 | H19: Medium
A20: T-F12-005 | B20: Kiểm tra Reject ứng viên ở trạng thái Application Initiated | C20: Tiền điều kiện: Truy cập https://opensource-demo.orangehrmlive.com/web/index.php/auth/login, đăng nhập Admin / admin123; đã có ứng viên mới tạo (theo T-F11-005, mỗi test dùng 1 ứng viên riêng) ở đúng trạng thái đầu vào của test, đang ở trang chi tiết ứng viên. 1. Nhấp [Reject]. 2. Nhập Notes = "Không đủ kinh nghiệm" 3. Nhấp [Save]. | D20: 1. Hiển thị "Successfully Saved" 2. Status chuyển "Rejected" | E20: T-F12-001 | F20: Pass | G20: 46322 | H20: High
A21: T-F12-006 | B21: Kiểm tra Reject ứng viên ở trạng thái Shortlisted | C21: Tiền điều kiện: Truy cập https://opensource-demo.orangehrmlive.com/web/index.php/auth/login, đăng nhập Admin / admin123; đã có ứng viên mới tạo (theo T-F11-005, mỗi test dùng 1 ứng viên riêng) ở đúng trạng thái đầu vào của test, đang ở trang chi tiết ứng viên. 1. Với ứng viên đã Shortlisted, nhấp [Reject]. 2. Nhấp [Save]. | D21: Status chuyển "Rejected" | E21: T-F12-003 | F21: Pass | G21: 46322 | H21: Medium
B22: Phỏng vấn
A23: T-F12-007 | B23: Kiểm tra lên lịch phỏng vấn với đầy đủ thông tin | C23: Tiền điều kiện: Truy cập https://opensource-demo.orangehrmlive.com/web/index.php/auth/login, đăng nhập Admin / admin123; đã có ứng viên mới tạo (theo T-F11-005, mỗi test dùng 1 ứng viên riêng) ở đúng trạng thái đầu vào của test, đang ở trang chi tiết ứng viên. 1. Với ứng viên Shortlisted, nhấp [Schedule Interview]. 2. Nhập Interview Title = "Phỏng vấn vòng 1" 3. Nhập Interviewer = "a" và chọn gợi ý. 4. Chọn Date = ngày mai, Time = 09:00. 5. Nhập Notes, nhấp [Save]. | D23: 1. Hiển thị "Successfully Saved" 2. Status chuyển "Interview Scheduled" 3. Hiển thị nút [Mark Interview Passed], [Mark Interview Failed]. | E23: T-F12-003 | F23: Pass | G23: 46322 | H23: High
A24: T-F12-008 | B24: Kiểm tra lên lịch phỏng vấn chỉ với trường bắt buộc | C24: Tiền điều kiện: Truy cập https://opensource-demo.orangehrmlive.com/web/index.php/auth/login, đăng nhập Admin / admin123; đã có ứng viên mới tạo (theo T-F11-005, mỗi test dùng 1 ứng viên riêng) ở đúng trạng thái đầu vào của test, đang ở trang chi tiết ứng viên. 1. Nhấp [Schedule Interview]. 2. Nhập Interview Title, Interviewer, Date hợp lệ. 3. Nhấp [Save]. | D24: Lưu thành công, Status = "Interview Scheduled" | E24: T-F12-003 | F24: Pass | G24: 46322 | H24: Medium | I24: Bắt buộc: Interview Title, Interviewer, Date
A25: T-F12-009 | B25: Kiểm tra đánh dấu Interview Passed | C25: Tiền điều kiện: Truy cập https://opensource-demo.orangehrmlive.com/web/index.php/auth/login, đăng nhập Admin / admin123; đã có ứng viên mới tạo (theo T-F11-005, mỗi test dùng 1 ứng viên riêng) ở đúng trạng thái đầu vào của test, đang ở trang chi tiết ứng viên. 1. Với ứng viên Interview Scheduled, nhấp [Mark Interview Passed]. 2. Nhấp [Save]. | D25: 1. Status chuyển "Interview Passed" 2. Hiển thị nút [Offer Job]. | E25: T-F12-007 | F25: Pass | G25: 46322 | H25: High
A26: T-F12-010 | B26: Kiểm tra đánh dấu Interview Failed | C26: Tiền điều kiện: Truy cập https://opensource-demo.orangehrmlive.com/web/index.php/auth/login, đăng nhập Admin / admin123; đã có ứng viên mới tạo (theo T-F11-005, mỗi test dùng 1 ứng viên riêng) ở đúng trạng thái đầu vào của test, đang ở trang chi tiết ứng viên. 1. Với ứng viên Interview Scheduled, nhấp [Mark Interview Failed]. 2. Nhấp [Save]. | D26: Status chuyển "Interview Failed" | E26: T-F12-007 | F26: Pass | G26: 46322 | H26: High
B27: Offer & Hire
A28: T-F12-011 | B28: Kiểm tra Offer Job cho ứng viên Interview Passed | C28: Tiền điều kiện: Truy cập https://opensource-demo.orangehrmlive.com/web/index.php/auth/login, đăng nhập Admin / admin123; đã có ứng viên mới tạo (theo T-F11-005, mỗi test dùng 1 ứng viên riêng) ở đúng trạng thái đầu vào của test, đang ở trang chi tiết ứng viên. 1. Nhấp [Offer Job]. 2. Nhập Notes, nhấp [Save]. | D28: 1. Status chuyển "Job Offered" 2. Hiển thị nút [Hire] và [Decline Offer]. | E28: T-F12-009 | F28: Pass | G28: 46322 | H28: High
A29: T-F12-012 | B29: Kiểm tra Decline Offer | C29: Tiền điều kiện: Truy cập https://opensource-demo.orangehrmlive.com/web/index.php/auth/login, đăng nhập Admin / admin123; đã có ứng viên mới tạo (theo T-F11-005, mỗi test dùng 1 ứng viên riêng) ở đúng trạng thái đầu vào của test, đang ở trang chi tiết ứng viên. 1. Với ứng viên Job Offered, nhấp [Decline Offer]. 2. Nhấp [Save]. | D29: Status chuyển "Offer Declined" | E29: T-F12-011 | F29: Pass | G29: 46322 | H29: Medium
A30: T-F12-013 | B30: Kiểm tra Hire ứng viên | C30: Tiền điều kiện: Truy cập https://opensource-demo.orangehrmlive.com/web/index.php/auth/login, đăng nhập Admin / admin123; đã có ứng viên mới tạo (theo T-F11-005, mỗi test dùng 1 ứng viên riêng) ở đúng trạng thái đầu vào của test, đang ở trang chi tiết ứng viên. 1. Với ứng viên Job Offered, nhấp [Hire]. 2. Nhấp [Save]. | D30: Status chuyển "Hired" | E30: T-F12-011 | F30: Pass | G30: 46322 | H30: High
A31: T-F12-014 | B31: Kiểm tra luồng đầy đủ: Initiated → Shortlisted → Interview Scheduled → Interview Passed → Job Offered → Hired | C31: Tiền điều kiện: Truy cập https://opensource-demo.orangehrmlive.com/web/index.php/auth/login, đăng nhập Admin / admin123; đã có ứng viên mới tạo (theo T-F11-005, mỗi test dùng 1 ứng viên riêng) ở đúng trạng thái đầu vào của test, đang ở trang chi tiết ứng viên. 1. Tạo ứng viên mới. 2. Lần lượt thực hiện: Shortlist → Schedule Interview → Mark Interview Passed → Offer Job → Hire. | D31: 1. Mỗi bước hiển thị "Successfully Saved" và Status đổi đúng thứ tự. 2. Kết thúc ở trạng thái "Hired" | E31: T-F11-005 | F31: Pass | G31: 46322 | H31: High | I31: End-to-end
B32: 12.3. Cập nhật không hợp lệ & ngoại lệ
B33: Lên lịch phỏng vấn không hợp lệ
A34: T-F12-015 | B34: Kiểm tra bỏ trống Interview Title | C34: Tiền điều kiện: Truy cập https://opensource-demo.orangehrmlive.com/web/index.php/auth/login, đăng nhập Admin / admin123; đã có ứng viên mới tạo (theo T-F11-005, mỗi test dùng 1 ứng viên riêng) ở đúng trạng thái đầu vào của test, đang ở trang chi tiết ứng viên. 1. Nhấp [Schedule Interview]. 2. Để trống Interview Title, nhập các trường khác hợp lệ. 3. Nhấp [Save]. | D34: 1. Hiển thị lỗi "Required" dưới Interview Title. 2. Status không đổi. | E34: T-F12-003 | F34: Pass | G34: 46322 | H34: High | I34: Negative
A35: T-F12-016 | B35: Kiểm tra bỏ trống Interviewer | C35: Tiền điều kiện: Truy cập https://opensource-demo.orangehrmlive.com/web/index.php/auth/login, đăng nhập Admin / admin123; đã có ứng viên mới tạo (theo T-F11-005, mỗi test dùng 1 ứng viên riêng) ở đúng trạng thái đầu vào của test, đang ở trang chi tiết ứng viên. 1. Nhấp [Schedule Interview]. 2. Nhập Interview Title, Date hợp lệ, để trống Interviewer. 3. Nhấp [Save]. | D35: 1. Hiển thị lỗi "Required" dưới Interviewer. 2. Status không đổi. | E35: T-F12-003 | F35: Pass | G35: 46322 | H35: High | I35: Negative
A36: T-F12-017 | B36: Kiểm tra bỏ trống Date | C36: Tiền điều kiện: Truy cập https://opensource-demo.orangehrmlive.com/web/index.php/auth/login, đăng nhập Admin / admin123; đã có ứng viên mới tạo (theo T-F11-005, mỗi test dùng 1 ứng viên riêng) ở đúng trạng thái đầu vào của test, đang ở trang chi tiết ứng viên. 1. Nhấp [Schedule Interview]. 2. Nhập Interview Title, Interviewer hợp lệ, để trống Date. 3. Nhấp [Save]. | D36: 1. Hiển thị lỗi "Required" dưới Date. 2. Status không đổi. | E36: T-F12-003 | F36: Pass | G36: 46322 | H36: High | I36: Negative
A37: T-F12-018 | B37: Kiểm tra nhập Interviewer không tồn tại | C37: Tiền điều kiện: Truy cập https://opensource-demo.orangehrmlive.com/web/index.php/auth/login, đăng nhập Admin / admin123; đã có ứng viên mới tạo (theo T-F11-005, mỗi test dùng 1 ứng viên riêng) ở đúng trạng thái đầu vào của test, đang ở trang chi tiết ứng viên. 1. Nhấp [Schedule Interview]. 2. Nhập Interviewer = "zzzzqqq" (không chọn gợi ý) 3. Nhấp [Save]. | D37: 1. Hiển thị lỗi "Invalid" tại Interviewer. 2. Status không đổi. | E37: T-F12-003 | F37: Fail | G37: 46322 | H37: Medium | I37: Negative Defect phát hiện: Hệ thống không hiển thị lỗi "Invalid" khi người dùng nhập tên Interviewer không tồn tại.
A38: T-F12-019 | B38: Kiểm tra nhập Date sai định dạng | C38: Tiền điều kiện: Truy cập https://opensource-demo.orangehrmlive.com/web/index.php/auth/login, đăng nhập Admin / admin123; đã có ứng viên mới tạo (theo T-F11-005, mỗi test dùng 1 ứng viên riêng) ở đúng trạng thái đầu vào của test, đang ở trang chi tiết ứng viên. 1. Nhấp [Schedule Interview]. 2. Nhập Date = "abc" 3. Nhấp [Save]. | D38: 1. Hiển thị lỗi định dạng ngày hợp lệ. 2. Status không đổi. | E38: T-F12-003 | F38: Fail | G38: 46322 | H38: Medium | I38: Negative Defect phát hiện: Hệ thống không hiển thị lỗi định dạng ngày hợp lệ khi nhập chuỗi "abc" vào trường Date phỏng vấn.
A39: T-F12-020 | B39: Kiểm tra Notes vượt độ dài tối đa (251 ký tự) | C39: Tiền điều kiện: Truy cập https://opensource-demo.orangehrmlive.com/web/index.php/auth/login, đăng nhập Admin / admin123; đã có ứng viên mới tạo (theo T-F11-005, mỗi test dùng 1 ứng viên riêng) ở đúng trạng thái đầu vào của test, đang ở trang chi tiết ứng viên. 1. Nhấp [Shortlist]. 2. Nhập Notes gồm 251 ký tự. 3. Nhấp [Save]. | D39: 1. Hiển thị lỗi "Should not exceed 250 characters" 2. Status không đổi. | E39: T-F12-001 | F39: Fail | G39: 46322 | H39: Medium | I39: Boundary; giới hạn 250 ký tự Defect phát hiện: Hệ thống không hiển thị thông báo lỗi "Should not exceed 250 characters" khi Notes vượt quá 250 ký tự.
B40: Workflow & ngoại lệ
A41: T-F12-021 | B41: Kiểm tra nhấn [Cancel] khi đang cập nhật trạng thái | C41: Tiền điều kiện: Truy cập https://opensource-demo.orangehrmlive.com/web/index.php/auth/login, đăng nhập Admin / admin123; đã có ứng viên mới tạo (theo T-F11-005, mỗi test dùng 1 ứng viên riêng) ở đúng trạng thái đầu vào của test, đang ở trang chi tiết ứng viên. 1. Nhấp [Shortlist], nhập Notes. 2. Nhấp [Cancel]. | D41: Quay về màn hình Application Stage, Status giữ nguyên "Application Initiated" | E41: T-F12-001 | F41: Pass | G41: 46322 | H41: Medium
A42: T-F12-022 | B42: Kiểm tra ứng viên Hired không còn thao tác chuyển trạng thái sai workflow | C42: Tiền điều kiện: Truy cập https://opensource-demo.orangehrmlive.com/web/index.php/auth/login, đăng nhập Admin / admin123; đã có ứng viên mới tạo (theo T-F11-005, mỗi test dùng 1 ứng viên riêng) ở đúng trạng thái đầu vào của test, đang ở trang chi tiết ứng viên. 1. Mở ứng viên có Status = "Hired" | D42: 1. Không hiển thị các nút [Shortlist], [Reject], [Schedule Interview]. 2. Status giữ nguyên "Hired" | E42: T-F12-014 | F42: Fail | G42: 46322 | H42: High | I42: Negative; Workflow Defect quy trình (Workflow): Ứng viên ở trạng thái "Hired" vẫn còn hiển thị nút chuyển trạng thái không hợp lệ.
A43: T-F12-023 | B43: Kiểm tra các nút thao tác phù hợp với từng trạng thái hiện tại | C43: Tiền điều kiện: Truy cập https://opensource-demo.orangehrmlive.com/web/index.php/auth/login, đăng nhập Admin / admin123; đã có ứng viên mới tạo (theo T-F11-005, mỗi test dùng 1 ứng viên riêng) ở đúng trạng thái đầu vào của test, đang ở trang chi tiết ứng viên. 1. Mở ứng viên ở trạng thái Application Initiated. 2. Quan sát các nút thao tác. | D43: Chỉ có [Reject], [Shortlist]; không có [Hire], [Offer Job], [Mark Interview Passed]. | E43: T-F12-001 | F43: Pass | G43: 46322 | H43: High | I43: Workflow
...

Sheet Test Report
B1: TEST REPORT
B3: Project Name | C3: =Cover!C4 -> OrangeHRM - Recruitment | E3: Creator | G3: Huỳnh Thị Ngọc Trân
B4: Project Code | C4: =Cover!C5 -> OHRM-REC | E4: Reviewer/Approver
B5: Document Code | C5: =C4&"_"&"Test Report"&"_"&"v0.1" -> OHRM-REC_Test Report_v0.1 | E5: Issue Date | G5: 46322
B6: Notes | C6: Release 1 gồm các module: OHRM_REC_Vacancy (F10), OHRM_REC_Candidate (F11), OHRM_REC_Status (F12) - OrangeHRM Recruitment
B10: No | C10: Module code | D10: Pass | E10: Fail | F10: Untested | G10: Blocked | H10: Skipped | I10: Number of test cases
B11: 1 | C11: =F10_Vacancy!B2 -> OHRM_REC_Vacancy | D11: =F10_Vacancy!A7 -> 0 | E11: =F10_Vacancy!B7 -> 1 | F11: =F10_Vacancy!C7 -> 33 | G11: =F10_Vacancy!D7 -> 0 | H11: =F10_Vacancy!E7 -> 0 | I11: =F10_Vacancy!F7 -> 34
B12: 2 | C12: =F11_Candidate!B2 -> OHRM_REC_Candidate | D12: =F11_Candidate!A7 -> 7 | E12: =F11_Candidate!B7 -> 1 | F12: =F11_Candidate!C7 -> 28 | G12: =F11_Candidate!D7 -> 0 | H12: =F11_Candidate!E7 -> 0 | I12: =F11_Candidate!F7 -> 36
B13: 3 | C13: =F12_Status!B2 -> OHRM_REC_Status | D13: =F12_Status!A7 -> 23 | E13: =F12_Status!B7 -> 5 | F13: =F12_Status!C7 -> 0 | G13: =F12_Status!D7 -> 0 | H13: =F12_Status!E7 -> 0 | I13: =F12_Status!F7 -> 28
C15: Sub total | D15: =SUM(D9:D14) -> 30 | E15: =SUM(E9:E14) -> 7 | F15: =SUM(F9:F14) -> 61 | G15: =SUM(G9:G14) -> 0 | H15: =SUM(H9:H14) -> 0 | I15: =SUM(I9:I14) -> 98
C17: Test coverage | E17: =IF((I15-H15-G15)=0,0,(D15+E15)*100/(I15-H15-G15)) -> 37.755102 | F17: %
C18: Test successful coverage | E18: =IF((D15+E15)=0,0,D15*100/(D15+E15)) -> 81.081081 | F18: %
