Workbook

Sheet Cover
B2: TEST CASE
B4: Project Name | C4: OrangeHRM - Time (Timesheets) | F4: Creator | G4: Nguyễn Thị Hồng Châu
B5: Project Code | C5: OHRM-TIME | F5: Reviewer/Approver | G5: Ngô Thanh Vy
B6: Document Code | C6: =C5&"_TestCase_V0.1" -> OHRM-TIME_TestCase_V0.1 | F6: Issue Date | G6: 46322
F7: Version | G7: 0.1
B10: Record of change
B11: Effective Date | C11: Version | D11: Change Item | E11: *A,D,M | F11: Change description | G11: Reference
B12: 46322 | C12: 0.1 | E12: A | F12: Tạo mới Test Design và Test Case cho F07, F08, F09 (module Time) | G12: Bảng phân công module (TV3); OrangeHRM 5.x demo
B14: *A: Added, D: Deleted, M: Modified

Sheet Test case List
D1: TEST CASE LIST
B3: Project Name | D3: =Cover!C4 -> OrangeHRM - Time (Timesheets)
B4: Project Code | D4: =Cover!C5 -> OHRM-TIME
B5: Test Environment Setup Description | D5: 1. Hệ thống: OrangeHRM 5.x bản demo (https://opensource-demo.orangehrmlive.com) hoặc bản cài local cùng phiên bản 2. Trình duyệt: Google Chrome bản mới nhất (tắt extension chặn script) 3. Tài khoản: Admin / admin123; ESS 'ess_test' (nhân viên 'Test Employee'); Supervisor 'sup_test' (nhân viên 'Test Supervisor', là supervisor của 'Test Employee'); nhân viên 'Test Employee2' (không phải cấp dưới của Supervisor) 4. Dữ liệu nền: Time > Project Info có Customer 'CUS_Test'; Project 'PRJ_Alpha' (Activity 'Development', 'Testing'); Project 'PRJ_Beta' (Activity 'Support') 5. Kỳ timesheet tính theo tuần (Thứ Hai – Chủ Nhật); mọi test chạy ở kỳ hiện tại trừ khi ghi chú khác
B8: No | C8: Function Name | D8: Sheet Name | E8: Description | F8: Pre-Condition
B9: 1 | C9: F07. Tạo timesheet | D9: F07_TaoTimesheet | E9: Nhân viên tạo timesheet tuần: chọn Project/Activity, nhập giờ từng ngày, comment, thêm/xóa hàng, lưu/hủy/reset. | F9: + Đăng nhập bằng tài khoản ESS 'ess_test' (liên kết nhân viên 'Test Employee') + Đã có dữ liệu dự án (Time > Project Info): Customer 'CUS_Test'; Project 'PRJ_Alpha' (Activity: 'Development', 'Testing'); Project 'PRJ_Beta' (Activity: 'Support') + 'Test Employee' chưa có timesheet ở kỳ (tuần) hiện tại
B10: 2 | C10: F08. Tra cứu timesheet | D10: F08_TraCuuTimesheet | E10: Xem timesheet của bản thân (My Timesheets), tra cứu theo nhân viên (Employee Timesheets), danh sách Pending Action, điều hướng kỳ. | F10: + Đăng nhập bằng tài khoản Admin (Admin / admin123) + 'Test Employee' có timesheet kỳ hiện tại trạng thái 'Submitted': PRJ_Alpha / Development, Mon–Fri mỗi ngày 08:00 (tổng 40:00) + 'Test Employee2' chưa có timesheet nào
B11: 3 | C11: F09. Gửi và xử lý timesheet | D11: F09_GuiVaXuLy | E11: Nhân viên gửi (Submit) timesheet; Admin/Supervisor xem, phê duyệt (Approve), từ chối (Reject), reset; nhân viên sửa và gửi lại. | F11: + Đăng nhập bằng tài khoản ESS 'ess_test' (liên kết nhân viên 'Test Employee') + 'Test Employee' có timesheet kỳ hiện tại trạng thái 'Not Submitted': PRJ_Alpha / Development, Thứ Hai–Thứ Sáu mỗi ngày 08:00 (tổng 40:00) + Có tài khoản Admin (Admin / admin123) để phê duyệt/từ chối
C13: Ghi chú
C14: - Result: Passed / Failed / Blocked / Skipped / Untested (chọn từ danh sách ở cột Result). Toàn bộ test case hiện ở trạng thái Untested; cột Test date và Note điền khi chạy test.
C15: - Cột Inter-test case Dependence: ghi ID test case phải chạy trước, hoặc vai trò đăng nhập cần dùng.
C16: - Expected Output dựa trên hành vi chuẩn của OrangeHRM 5.x. Test case có ghi chú 'Cần đối chiếu...' ở cột Note: so khớp thông báo/hành vi thực tế rồi cập nhật Expected Output nếu khác.
C17: - Loại test (TestDesign): Function, GUI, Boundary (giá trị biên), Negative (giá trị không hợp lệ), Security.

Sheet TestDesign
A1: Requirement Level 1 | B1: Requirement Level 2 | C1: Requirement Level 3 | D1: Test Criteria | E1: Test Type | F1: Note | G1: Test Case ID
A2: F07. Tạo timesheet | B2: 7.1 Hiển thị màn hình tạo timesheet | C2: Displaying | D2: Kiểm tra hiển thị nút [Create Timesheet] khi nhân viên chưa có timesheet ở kỳ hiện tại | E2: Function | G2: =F07_TaoTimesheet!A9 -> TIME_CreateTimesheet_01
D3: Kiểm tra layout màn hình Edit Timesheet sau khi click [Create Timesheet] | E3: GUI | F3: Cần đối chiếu hành vi/thông báo thực tế trên OrangeHRM 5.x khi chạy test | G3: =F07_TaoTimesheet!A10 -> TIME_CreateTimesheet_02
D4: Kiểm tra giá trị mặc định trên màn hình Edit Timesheet | E4: GUI | G4: =F07_TaoTimesheet!A11 -> TIME_CreateTimesheet_03
B5: 7.2 Tạo timesheet - dữ liệu giờ | C5: Giá trị hợp lệ | D5: Kiểm tra tạo timesheet hợp lệ: 1 hàng, 1 ngày, giờ nhập dạng HH:MM (08:00) | E5: Function | G5: =F07_TaoTimesheet!A12 -> TIME_CreateTimesheet_04
D6: Kiểm tra nhập giờ dạng số nguyên '8' được chuẩn hóa thành 08:00 | E6: Function | G6: =F07_TaoTimesheet!A13 -> TIME_CreateTimesheet_05
D7: Kiểm tra nhập giờ dạng thập phân '7.5' được chuẩn hóa thành 07:30 | E7: Function | F7: Cần đối chiếu hành vi/thông báo thực tế trên OrangeHRM 5.x khi chạy test | G7: =F07_TaoTimesheet!A14 -> TIME_CreateTimesheet_06
D8: Kiểm tra nhập giờ dạng H:MM '8:30' | E8: Function | G8: =F07_TaoTimesheet!A15 -> TIME_CreateTimesheet_07
D9: Kiểm tra tạo timesheet có giờ cho cả 7 ngày (mỗi ngày 08:00) | E9: Function | G9: =F07_TaoTimesheet!A16 -> TIME_CreateTimesheet_08
D10: Kiểm tra tạo timesheet nhiều hàng với 2 Project khác nhau | E10: Function | G10: =F07_TaoTimesheet!A17 -> TIME_CreateTimesheet_09
D11: Kiểm tra tạo timesheet nhiều hàng cùng Project nhưng khác Activity | E11: Function | G11: =F07_TaoTimesheet!A18 -> TIME_CreateTimesheet_10
D12: Kiểm tra thêm nhiều hàng bằng [Add Row] | E12: Function | G12: =F07_TaoTimesheet!A19 -> TIME_CreateTimesheet_11
D13: Kiểm tra xóa 1 hàng trước khi lưu | E13: Function | G13: =F07_TaoTimesheet!A20 -> TIME_CreateTimesheet_12
D14: Kiểm tra thêm comment hợp lệ cho ô giờ | E14: Function | G14: =F07_TaoTimesheet!A21 -> TIME_CreateTimesheet_13
D15: Kiểm tra click [Cancel] khi đang nhập dữ liệu | E15: Function | G15: =F07_TaoTimesheet!A22 -> TIME_CreateTimesheet_14
D16: Kiểm tra click [Reset] khi đang nhập dữ liệu | E16: Function | F16: Cần đối chiếu hành vi/thông báo thực tế trên OrangeHRM 5.x khi chạy test | G16: =F07_TaoTimesheet!A23 -> TIME_CreateTimesheet_15
C17: Giá trị biên | D17: Kiểm tra biên dưới: nhập giờ = 00:00 | E17: Boundary | F17: Cần đối chiếu hành vi/thông báo thực tế trên OrangeHRM 5.x khi chạy test | G17: =F07_TaoTimesheet!A24 -> TIME_CreateTimesheet_16
D18: Kiểm tra biên dưới + 1 đơn vị: nhập giờ = 00:01 | E18: Boundary | G18: =F07_TaoTimesheet!A25 -> TIME_CreateTimesheet_17
D19: Kiểm tra biên trên hợp lệ: nhập giờ = 23:59 cho 1 ngày | E19: Boundary | G19: =F07_TaoTimesheet!A26 -> TIME_CreateTimesheet_18
D20: Kiểm tra biên trên: nhập giờ = 24:00 cho 1 ngày | E20: Boundary | F20: Cần đối chiếu hành vi/thông báo thực tế trên OrangeHRM 5.x khi chạy test | G20: =F07_TaoTimesheet!A27 -> TIME_CreateTimesheet_19
D21: Kiểm tra vượt biên trên: nhập giờ = 24:01 | E21: Boundary | G21: =F07_TaoTimesheet!A28 -> TIME_CreateTimesheet_20
D22: Kiểm tra giá trị rất lớn: nhập giờ = 100 | E22: Boundary | G22: =F07_TaoTimesheet!A29 -> TIME_CreateTimesheet_21
D23: Kiểm tra biên phút hợp lệ: nhập giờ = 08:59 | E23: Boundary | G23: =F07_TaoTimesheet!A30 -> TIME_CreateTimesheet_22
D24: Kiểm tra vượt biên phút: nhập giờ = 08:60 | E24: Boundary | F24: Cần đối chiếu hành vi/thông báo thực tế trên OrangeHRM 5.x khi chạy test | G24: =F07_TaoTimesheet!A31 -> TIME_CreateTimesheet_23
D25: Kiểm tra tổng giờ trong 1 ngày qua nhiều hàng vượt 24:00 (12:00 + 13:00) | E25: Boundary | F25: Cần xác nhận: OrangeHRM có thể chỉ kiểm tra giới hạn trên từng ô, không kiểm tra tổng/ngày | G25: =F07_TaoTimesheet!A32 -> TIME_CreateTimesheet_24
D26: Kiểm tra comment dài đúng 250 ký tự | E26: Boundary | F26: Cần đối chiếu hành vi/thông báo thực tế trên OrangeHRM 5.x khi chạy test | G26: =F07_TaoTimesheet!A33 -> TIME_CreateTimesheet_25
D27: Kiểm tra comment dài 251 ký tự (vượt biên) | E27: Boundary | F27: Cần đối chiếu hành vi/thông báo thực tế trên OrangeHRM 5.x khi chạy test | G27: =F07_TaoTimesheet!A34 -> TIME_CreateTimesheet_26
C28: Giá trị không hợp lệ | D28: Kiểm tra lưu khi không chọn Project và Activity (đã nhập giờ) | E28: Negative | G28: =F07_TaoTimesheet!A35 -> TIME_CreateTimesheet_27
D29: Kiểm tra lưu khi đã chọn Project nhưng bỏ trống Activity | E29: Negative | G29: =F07_TaoTimesheet!A36 -> TIME_CreateTimesheet_28
D30: Kiểm tra gõ Project Name nhưng không chọn từ danh sách gợi ý | E30: Negative | G30: =F07_TaoTimesheet!A37 -> TIME_CreateTimesheet_29
D31: Kiểm tra Project Name không tồn tại ('PRJ_NotExist') | E31: Negative | G31: =F07_TaoTimesheet!A38 -> TIME_CreateTimesheet_30
D32: Kiểm tra nhập giờ là chữ ('abc') | E32: Negative | G32: =F07_TaoTimesheet!A39 -> TIME_CreateTimesheet_31
D33: Kiểm tra nhập giờ âm ('-1') | E33: Negative | G33: =F07_TaoTimesheet!A40 -> TIME_CreateTimesheet_32
D34: Kiểm tra nhập giờ chứa ký tự đặc biệt ('8@#') | E34: Negative | G34: =F07_TaoTimesheet!A41 -> TIME_CreateTimesheet_33
D35: Kiểm tra 2 hàng trùng cặp Project + Activity | E35: Negative | F35: Cần đối chiếu hành vi/thông báo thực tế trên OrangeHRM 5.x khi chạy test | G35: =F07_TaoTimesheet!A42 -> TIME_CreateTimesheet_34
D36: Kiểm tra lưu khi toàn bộ lưới để trống | E36: Negative | F36: Cần đối chiếu hành vi/thông báo thực tế trên OrangeHRM 5.x khi chạy test | G36: =F07_TaoTimesheet!A43 -> TIME_CreateTimesheet_35
B37: 7.3 Ràng buộc, bảo mật và độ ổn định | C37: Constraint / Security | D37: Kiểm tra kỳ đã có timesheet thì không cho tạo trùng | E37: Function | G37: =F07_TaoTimesheet!A44 -> TIME_CreateTimesheet_36
D38: Kiểm tra dữ liệu vẫn được giữ sau khi đăng xuất và đăng nhập lại | E38: Function | G38: =F07_TaoTimesheet!A45 -> TIME_CreateTimesheet_37
D39: Kiểm tra nhấn đúp [Save] liên tiếp | E39: Negative | G39: =F07_TaoTimesheet!A46 -> TIME_CreateTimesheet_38
D40: Kiểm tra XSS trong comment: <script>alert('xss')</script> | E40: Security | G40: =F07_TaoTimesheet!A47 -> TIME_CreateTimesheet_39
...

Sheet F07_TaoTimesheet
A2: Module Code | B2: TIME_CreateTimesheet | J2: Passed
A3: Test requirement | B3: F07. Tạo timesheet | J3: Failed
A4: Tester | B4: =Cover!G4 -> Nguyễn Thị Hồng Châu | J4: Blocked
A5: Passed | B5: Failed | C5: Untested | D5: Blocked | E5: Skipped | F5: Number of Test cases | J5: Untested
A6: =COUNTIF(F9:F90,"Passed") -> 0 | B6: =COUNTIF(F9:F90,"Failed") -> 0 | C6: =F6-E6-D6-B6-A6 -> 42 | D6: =COUNTIF(F9:F90,"Blocked") -> 0 | E6: =COUNTIF(F9:F90,"Skipped") -> 0 | F6: =COUNTA(A9:A90) -> 42 | J6: Skipped
A8: ID | B8: Test Case Description | C8: Test Case Procedure | D8: Expected Output | E8: Inter-test case Dependence | F8: Result | G8: Test date | H8: Note
A9: =IF(OR(B9<>"",D9<>""),$B$2&"_"&TEXT(ROW()-8,"00"),"") -> TIME_CreateTimesheet_01 | B9: Kiểm tra hiển thị nút [Create Timesheet] khi nhân viên chưa có timesheet ở kỳ hiện tại | C9: Pre-condition: + Đăng nhập bằng tài khoản ESS 'ess_test' (liên kết nhân viên 'Test Employee') + Đã có dữ liệu dự án (Time > Project Info): Customer 'CUS_Test'; Project 'PRJ_Alpha' (Activity: 'Development', 'Testing'); Project 'PRJ_Beta' (Activity: 'Support') + 'Test Employee' chưa có timesheet ở kỳ (tuần) hiện tại Step: 1. Chọn menu Time > Timesheets > My Timesheets | D9: 1. Trang My Timesheets hiển thị kỳ (tuần) hiện tại từ Thứ Hai đến Chủ Nhật 2. Nút [Create Timesheet] được hiển thị; chưa có dòng dữ liệu giờ nào | E9: Đăng nhập với role ESS | F9: Untested
A10: =IF(OR(B10<>"",D10<>""),$B$2&"_"&TEXT(ROW()-8,"00"),"") -> TIME_CreateTimesheet_02 | B10: Kiểm tra layout màn hình Edit Timesheet sau khi click [Create Timesheet] | C10: Pre-condition: + Đăng nhập bằng tài khoản ESS 'ess_test' (liên kết nhân viên 'Test Employee') + Đã có dữ liệu dự án (Time > Project Info): Customer 'CUS_Test'; Project 'PRJ_Alpha' (Activity: 'Development', 'Testing'); Project 'PRJ_Beta' (Activity: 'Support') + 'Test Employee' chưa có timesheet ở kỳ (tuần) hiện tại Step: 1. Chọn menu Time > Timesheets > My Timesheets 2. Click nút [Create Timesheet] | D10: 1. Màn hình Edit Timesheet hiển thị đúng kỳ timesheet 2. Có cột Project Name, Activity, 7 cột ngày (Mon–Sun), cột Total; có các nút [Add Row], [Cancel], [Reset], [Save]; căn chỉnh, font, nhãn hiển thị đúng | E10: Đăng nhập với role ESS | F10: Untested | H10: Cần đối chiếu hành vi/thông báo thực tế trên OrangeHRM 5.x khi chạy test
A11: =IF(OR(B11<>"",D11<>""),$B$2&"_"&TEXT(ROW()-8,"00"),"") -> TIME_CreateTimesheet_03 | B11: Kiểm tra giá trị mặc định trên màn hình Edit Timesheet | C11: Pre-condition: + Đăng nhập bằng tài khoản ESS 'ess_test' (liên kết nhân viên 'Test Employee') + Đã có dữ liệu dự án (Time > Project Info): Customer 'CUS_Test'; Project 'PRJ_Alpha' (Activity: 'Development', 'Testing'); Project 'PRJ_Beta' (Activity: 'Support') + 'Test Employee' chưa có timesheet ở kỳ (tuần) hiện tại Step: 1. Chọn menu Time > Timesheets > My Timesheets 2. Click nút [Create Timesheet] | D11: 2. Có 1 hàng trống; Project Name, Activity chưa chọn; các ô giờ để trống; tổng giờ = 00:00 | E11: Đăng nhập với role ESS | F11: Untested
A12: =IF(OR(B12<>"",D12<>""),$B$2&"_"&TEXT(ROW()-8,"00"),"") -> TIME_CreateTimesheet_04 | B12: Kiểm tra tạo timesheet hợp lệ: 1 hàng, 1 ngày, giờ nhập dạng HH:MM (08:00) | C12: Pre-condition: + Đăng nhập bằng tài khoản ESS 'ess_test' (liên kết nhân viên 'Test Employee') + Đã có dữ liệu dự án (Time > Project Info): Customer 'CUS_Test'; Project 'PRJ_Alpha' (Activity: 'Development', 'Testing'); Project 'PRJ_Beta' (Activity: 'Support') + 'Test Employee' chưa có timesheet ở kỳ (tuần) hiện tại Step: 1. Chọn menu Time > Timesheets > My Timesheets 2. Click nút [Create Timesheet] 3. Tại Project Name gõ 'PRJ_A' và chọn 'PRJ_Alpha' từ danh sách gợi ý 4. Chọn Activity = 'Development' 5. Nhập '08:00' vào cột Mon 6. Click nút [Save] | D12: 5. Hiển thị thông báo lưu thành công 6. Trở về My Timesheets: timesheet kỳ hiện tại có Mon = 08:00, Total = 08:00, trạng thái 'Not Submitted' | E12: Đăng nhập với role ESS | F12: Untested
A13: =IF(OR(B13<>"",D13<>""),$B$2&"_"&TEXT(ROW()-8,"00"),"") -> TIME_CreateTimesheet_05 | B13: Kiểm tra nhập giờ dạng số nguyên '8' được chuẩn hóa thành 08:00 | C13: Pre-condition: + Đăng nhập bằng tài khoản ESS 'ess_test' (liên kết nhân viên 'Test Employee') + Đã có dữ liệu dự án (Time > Project Info): Customer 'CUS_Test'; Project 'PRJ_Alpha' (Activity: 'Development', 'Testing'); Project 'PRJ_Beta' (Activity: 'Support') + 'Test Employee' chưa có timesheet ở kỳ (tuần) hiện tại Step: 1. Chọn menu Time > Timesheets > My Timesheets 2. Click nút [Create Timesheet] 3. Tại Project Name gõ 'PRJ_A' và chọn 'PRJ_Alpha' từ danh sách gợi ý 4. Chọn Activity = 'Development' 5. Nhập '8' vào cột Tue 6. Click nút [Save] | D13: 6. Lưu thành công; ô Tue hiển thị 08:00, Total = 08:00 | E13: Đăng nhập với role ESS | F13: Untested
A14: =IF(OR(B14<>"",D14<>""),$B$2&"_"&TEXT(ROW()-8,"00"),"") -> TIME_CreateTimesheet_06 | B14: Kiểm tra nhập giờ dạng thập phân '7.5' được chuẩn hóa thành 07:30 | C14: Pre-condition: + Đăng nhập bằng tài khoản ESS 'ess_test' (liên kết nhân viên 'Test Employee') + Đã có dữ liệu dự án (Time > Project Info): Customer 'CUS_Test'; Project 'PRJ_Alpha' (Activity: 'Development', 'Testing'); Project 'PRJ_Beta' (Activity: 'Support') + 'Test Employee' chưa có timesheet ở kỳ (tuần) hiện tại Step: 1. Chọn menu Time > Timesheets > My Timesheets 2. Click nút [Create Timesheet] 3. Tại Project Name gõ 'PRJ_A' và chọn 'PRJ_Alpha' từ danh sách gợi ý 4. Chọn Activity = 'Development' 5. Nhập '7.5' vào cột Wed 6. Click nút [Save] | D14: 6. Lưu thành công; ô Wed hiển thị 07:30, Total = 07:30 | E14: Đăng nhập với role ESS | F14: Untested | H14: Cần đối chiếu hành vi/thông báo thực tế trên OrangeHRM 5.x khi chạy test
A15: =IF(OR(B15<>"",D15<>""),$B$2&"_"&TEXT(ROW()-8,"00"),"") -> TIME_CreateTimesheet_07 | B15: Kiểm tra nhập giờ dạng H:MM '8:30' | C15: Pre-condition: + Đăng nhập bằng tài khoản ESS 'ess_test' (liên kết nhân viên 'Test Employee') + Đã có dữ liệu dự án (Time > Project Info): Customer 'CUS_Test'; Project 'PRJ_Alpha' (Activity: 'Development', 'Testing'); Project 'PRJ_Beta' (Activity: 'Support') + 'Test Employee' chưa có timesheet ở kỳ (tuần) hiện tại Step: 1. Chọn menu Time > Timesheets > My Timesheets 2. Click nút [Create Timesheet] 3. Tại Project Name gõ 'PRJ_A' và chọn 'PRJ_Alpha' từ danh sách gợi ý 4. Chọn Activity = 'Development' 5. Nhập '8:30' vào cột Thu 6. Click nút [Save] | D15: 6. Lưu thành công; ô Thu hiển thị 08:30, Total = 08:30 | E15: Đăng nhập với role ESS | F15: Untested
A16: =IF(OR(B16<>"",D16<>""),$B$2&"_"&TEXT(ROW()-8,"00"),"") -> TIME_CreateTimesheet_08 | B16: Kiểm tra tạo timesheet có giờ cho cả 7 ngày (mỗi ngày 08:00) | C16: Pre-condition: + Đăng nhập bằng tài khoản ESS 'ess_test' (liên kết nhân viên 'Test Employee') + Đã có dữ liệu dự án (Time > Project Info): Customer 'CUS_Test'; Project 'PRJ_Alpha' (Activity: 'Development', 'Testing'); Project 'PRJ_Beta' (Activity: 'Support') + 'Test Employee' chưa có timesheet ở kỳ (tuần) hiện tại Step: 1. Chọn menu Time > Timesheets > My Timesheets 2. Click nút [Create Timesheet] 3. Tại Project Name gõ 'PRJ_A' và chọn 'PRJ_Alpha' từ danh sách gợi ý 4. Chọn Activity = 'Development' 5. Nhập '08:00' vào cả 7 cột Mon–Sun 6. Click nút [Save] | D16: 6. Lưu thành công; tổng hàng = 56:00; tổng mỗi ngày = 08:00 | E16: Đăng nhập với role ESS | F16: Untested
A17: =IF(OR(B17<>"",D17<>""),$B$2&"_"&TEXT(ROW()-8,"00"),"") -> TIME_CreateTimesheet_09 | B17: Kiểm tra tạo timesheet nhiều hàng với 2 Project khác nhau | C17: Pre-condition: + Đăng nhập bằng tài khoản ESS 'ess_test' (liên kết nhân viên 'Test Employee') + Đã có dữ liệu dự án (Time > Project Info): Customer 'CUS_Test'; Project 'PRJ_Alpha' (Activity: 'Development', 'Testing'); Project 'PRJ_Beta' (Activity: 'Support') + 'Test Employee' chưa có timesheet ở kỳ (tuần) hiện tại Step: 1. Chọn menu Time > Timesheets > My Timesheets 2. Click nút [Create Timesheet] 3. Tại Project Name gõ 'PRJ_A' và chọn 'PRJ_Alpha' từ danh sách gợi ý 4. Chọn Activity = 'Development' 5. Nhập '04:00' vào cột Mon 6. Click [Add Row] 7. Tại Project Name gõ 'PRJ_B' và chọn 'PRJ_Beta' từ danh sách gợi ý 8. Chọn Activity = 'Support' 9. Nhập '04:00' vào cột Mon 10. Click nút [Save] | D17: 10. Lưu thành công; 2 hàng hiển thị đúng; tổng ngày Mon = 08:00; tổng mỗi hàng = 04:00 | E17: Đăng nhập với role ESS | F17: Untested
A18: =IF(OR(B18<>"",D18<>""),$B$2&"_"&TEXT(ROW()-8,"00"),"") -> TIME_CreateTimesheet_10 | B18: Kiểm tra tạo timesheet nhiều hàng cùng Project nhưng khác Activity | C18: Pre-condition: + Đăng nhập bằng tài khoản ESS 'ess_test' (liên kết nhân viên 'Test Employee') + Đã có dữ liệu dự án (Time > Project Info): Customer 'CUS_Test'; Project 'PRJ_Alpha' (Activity: 'Development', 'Testing'); Project 'PRJ_Beta' (Activity: 'Support') + 'Test Employee' chưa có timesheet ở kỳ (tuần) hiện tại Step: 1. Chọn menu Time > Timesheets > My Timesheets 2. Click nút [Create Timesheet] 3. Tại Project Name gõ 'PRJ_A' và chọn 'PRJ_Alpha' từ danh sách gợi ý 4. Chọn Activity = 'Development' 5. Nhập '03:00' vào cột Mon 6. Click [Add Row] 7. Tại Project Name gõ 'PRJ_A' và chọn 'PRJ_Alpha' từ danh sách gợi ý 8. Chọn Activity = 'Testing' 9. Nhập '05:00' vào cột Mon 10. Click nút [Save] | D18: 10. Lưu thành công (2 cặp Project/Activity khác nhau); tổng ngày Mon = 08:00 | E18: Đăng nhập với role ESS | F18: Untested
A19: =IF(OR(B19<>"",D19<>""),$B$2&"_"&TEXT(ROW()-8,"00"),"") -> TIME_CreateTimesheet_11 | B19: Kiểm tra thêm nhiều hàng bằng [Add Row] | C19: Pre-condition: + Đăng nhập bằng tài khoản ESS 'ess_test' (liên kết nhân viên 'Test Employee') + Đã có dữ liệu dự án (Time > Project Info): Customer 'CUS_Test'; Project 'PRJ_Alpha' (Activity: 'Development', 'Testing'); Project 'PRJ_Beta' (Activity: 'Support') + 'Test Employee' chưa có timesheet ở kỳ (tuần) hiện tại Step: 1. Chọn menu Time > Timesheets > My Timesheets 2. Click nút [Create Timesheet] 3. Click [Add Row] 3 lần | D19: 3. Màn hình có tổng cộng 4 hàng trống, mỗi hàng đều có Project Name, Activity và 7 ô giờ | E19: Đăng nhập với role ESS | F19: Untested
A20: =IF(OR(B20<>"",D20<>""),$B$2&"_"&TEXT(ROW()-8,"00"),"") -> TIME_CreateTimesheet_12 | B20: Kiểm tra xóa 1 hàng trước khi lưu | C20: Pre-condition: + Đăng nhập bằng tài khoản ESS 'ess_test' (liên kết nhân viên 'Test Employee') + Đã có dữ liệu dự án (Time > Project Info): Customer 'CUS_Test'; Project 'PRJ_Alpha' (Activity: 'Development', 'Testing'); Project 'PRJ_Beta' (Activity: 'Support') + 'Test Employee' chưa có timesheet ở kỳ (tuần) hiện tại Step: 1. Chọn menu Time > Timesheets > My Timesheets 2. Click nút [Create Timesheet] 3. Tại Project Name gõ 'PRJ_A' và chọn 'PRJ_Alpha' từ danh sách gợi ý 4. Chọn Activity = 'Development' 5. Nhập '08:00' vào Mon 6. Click [Add Row] 7. Tại Project Name gõ 'PRJ_B' và chọn 'PRJ_Beta' từ danh sách gợi ý 8. Chọn Activity = 'Support' 9. Nhập '02:00' vào Mon 10. Click biểu tượng xóa (thùng rác) ở hàng 2 11. Click nút [Save] | D20: 11. Hàng 2 bị xóa khỏi lưới; sau khi lưu chỉ còn hàng 1 (Mon = 08:00) | E20: Đăng nhập với role ESS | F20: Untested
A21: =IF(OR(B21<>"",D21<>""),$B$2&"_"&TEXT(ROW()-8,"00"),"") -> TIME_CreateTimesheet_13 | B21: Kiểm tra thêm comment hợp lệ cho ô giờ | C21: Pre-condition: + Đăng nhập bằng tài khoản ESS 'ess_test' (liên kết nhân viên 'Test Employee') + Đã có dữ liệu dự án (Time > Project Info): Customer 'CUS_Test'; Project 'PRJ_Alpha' (Activity: 'Development', 'Testing'); Project 'PRJ_Beta' (Activity: 'Support') + 'Test Employee' chưa có timesheet ở kỳ (tuần) hiện tại Step: 1. Chọn menu Time > Timesheets > My Timesheets 2. Click nút [Create Timesheet] 3. Tại Project Name gõ 'PRJ_A' và chọn 'PRJ_Alpha' từ danh sách gợi ý 4. Chọn Activity = 'Development' 5. Nhập '08:00' vào cột Mon 6. Click biểu tượng comment ở ô Mon, nhập 'Fix bug login', xác nhận 7. Click nút [Save] | D21: 7. Lưu thành công; ô Mon có biểu tượng comment; mở lại hiển thị nội dung 'Fix bug login' | E21: Đăng nhập với role ESS | F21: Untested
A22: =IF(OR(B22<>"",D22<>""),$B$2&"_"&TEXT(ROW()-8,"00"),"") -> TIME_CreateTimesheet_14 | B22: Kiểm tra click [Cancel] khi đang nhập dữ liệu | C22: Pre-condition: + Đăng nhập bằng tài khoản ESS 'ess_test' (liên kết nhân viên 'Test Employee') + Đã có dữ liệu dự án (Time > Project Info): Customer 'CUS_Test'; Project 'PRJ_Alpha' (Activity: 'Development', 'Testing'); Project 'PRJ_Beta' (Activity: 'Support') + 'Test Employee' chưa có timesheet ở kỳ (tuần) hiện tại Step: 1. Chọn menu Time > Timesheets > My Timesheets 2. Click nút [Create Timesheet] 3. Tại Project Name gõ 'PRJ_A' và chọn 'PRJ_Alpha' từ danh sách gợi ý 4. Chọn Activity = 'Development' 5. Nhập '08:00' vào cột Mon 6. Click [Cancel] | D22: 6. Trở về trang My Timesheets; không có timesheet nào được tạo; vẫn hiển thị nút [Create Timesheet] | E22: Đăng nhập với role ESS | F22: Untested
A23: =IF(OR(B23<>"",D23<>""),$B$2&"_"&TEXT(ROW()-8,"00"),"") -> TIME_CreateTimesheet_15 | B23: Kiểm tra click [Reset] khi đang nhập dữ liệu | C23: Pre-condition: + Đăng nhập bằng tài khoản ESS 'ess_test' (liên kết nhân viên 'Test Employee') + Đã có dữ liệu dự án (Time > Project Info): Customer 'CUS_Test'; Project 'PRJ_Alpha' (Activity: 'Development', 'Testing'); Project 'PRJ_Beta' (Activity: 'Support') + 'Test Employee' chưa có timesheet ở kỳ (tuần) hiện tại Step: 1. Chọn menu Time > Timesheets > My Timesheets 2. Click nút [Create Timesheet] 3. Tại Project Name gõ 'PRJ_A' và chọn 'PRJ_Alpha' từ danh sách gợi ý 4. Chọn Activity = 'Development' 5. Nhập '08:00' vào cột Mon 6. Click [Reset] | D23: 6. Toàn bộ dữ liệu vừa nhập bị xóa, màn hình trở về trạng thái ban đầu (1 hàng trống) | E23: Đăng nhập với role ESS | F23: Untested | H23: Cần đối chiếu hành vi/thông báo thực tế trên OrangeHRM 5.x khi chạy test
A24: =IF(OR(B24<>"",D24<>""),$B$2&"_"&TEXT(ROW()-8,"00"),"") -> TIME_CreateTimesheet_16 | B24: Kiểm tra biên dưới: nhập giờ = 00:00 | C24: Pre-condition: + Đăng nhập bằng tài khoản ESS 'ess_test' (liên kết nhân viên 'Test Employee') + Đã có dữ liệu dự án (Time > Project Info): Customer 'CUS_Test'; Project 'PRJ_Alpha' (Activity: 'Development', 'Testing'); Project 'PRJ_Beta' (Activity: 'Support') + 'Test Employee' chưa có timesheet ở kỳ (tuần) hiện tại Step: 1. Chọn menu Time > Timesheets > My Timesheets 2. Click nút [Create Timesheet] 3. Tại Project Name gõ 'PRJ_A' và chọn 'PRJ_Alpha' từ danh sách gợi ý 4. Chọn Activity = 'Development' 5. Nhập '00:00' vào cột Mon 6. Click nút [Save] | D24: 6. Giá trị 0 được chấp nhận và không báo lỗi định dạng; Total = 00:00 | E24: Đăng nhập với role ESS | F24: Untested | H24: Cần đối chiếu hành vi/thông báo thực tế trên OrangeHRM 5.x khi chạy test
A25: =IF(OR(B25<>"",D25<>""),$B$2&"_"&TEXT(ROW()-8,"00"),"") -> TIME_CreateTimesheet_17 | B25: Kiểm tra biên dưới + 1 đơn vị: nhập giờ = 00:01 | C25: Pre-condition: + Đăng nhập bằng tài khoản ESS 'ess_test' (liên kết nhân viên 'Test Employee') + Đã có dữ liệu dự án (Time > Project Info): Customer 'CUS_Test'; Project 'PRJ_Alpha' (Activity: 'Development', 'Testing'); Project 'PRJ_Beta' (Activity: 'Support') + 'Test Employee' chưa có timesheet ở kỳ (tuần) hiện tại Step: 1. Chọn menu Time > Timesheets > My Timesheets 2. Click nút [Create Timesheet] 3. Tại Project Name gõ 'PRJ_A' và chọn 'PRJ_Alpha' từ danh sách gợi ý 4. Chọn Activity = 'Development' 5. Nhập '00:01' vào cột Mon 6. Click nút [Save] | D25: 6. Lưu thành công; ô Mon hiển thị 00:01, Total = 00:01 | E25: Đăng nhập với role ESS | F25: Untested
A26: =IF(OR(B26<>"",D26<>""),$B$2&"_"&TEXT(ROW()-8,"00"),"") -> TIME_CreateTimesheet_18 | B26: Kiểm tra biên trên hợp lệ: nhập giờ = 23:59 cho 1 ngày | C26: Pre-condition: + Đăng nhập bằng tài khoản ESS 'ess_test' (liên kết nhân viên 'Test Employee') + Đã có dữ liệu dự án (Time > Project Info): Customer 'CUS_Test'; Project 'PRJ_Alpha' (Activity: 'Development', 'Testing'); Project 'PRJ_Beta' (Activity: 'Support') + 'Test Employee' chưa có timesheet ở kỳ (tuần) hiện tại Step: 1. Chọn menu Time > Timesheets > My Timesheets 2. Click nút [Create Timesheet] 3. Tại Project Name gõ 'PRJ_A' và chọn 'PRJ_Alpha' từ danh sách gợi ý 4. Chọn Activity = 'Development' 5. Nhập '23:59' vào cột Mon 6. Click nút [Save] | D26: 6. Lưu thành công; ô Mon hiển thị 23:59 | E26: Đăng nhập với role ESS | F26: Untested
A27: =IF(OR(B27<>"",D27<>""),$B$2&"_"&TEXT(ROW()-8,"00"),"") -> TIME_CreateTimesheet_19 | B27: Kiểm tra biên trên: nhập giờ = 24:00 cho 1 ngày | C27: Pre-condition: + Đăng nhập bằng tài khoản ESS 'ess_test' (liên kết nhân viên 'Test Employee') + Đã có dữ liệu dự án (Time > Project Info): Customer 'CUS_Test'; Project 'PRJ_Alpha' (Activity: 'Development', 'Testing'); Project 'PRJ_Beta' (Activity: 'Support') + 'Test Employee' chưa có timesheet ở kỳ (tuần) hiện tại Step: 1. Chọn menu Time > Timesheets > My Timesheets 2. Click nút [Create Timesheet] 3. Tại Project Name gõ 'PRJ_A' và chọn 'PRJ_Alpha' từ danh sách gợi ý 4. Chọn Activity = 'Development' 5. Nhập '24:00' vào cột Mon 6. Click nút [Save] | D27: 6. Hiển thị lỗi validation tại ô (ví dụ: 'Should be less than 24:00'); không lưu | E27: Đăng nhập với role ESS | F27: Untested | H27: Cần đối chiếu hành vi/thông báo thực tế trên OrangeHRM 5.x khi chạy test
A28: =IF(OR(B28<>"",D28<>""),$B$2&"_"&TEXT(ROW()-8,"00"),"") -> TIME_CreateTimesheet_20 | B28: Kiểm tra vượt biên trên: nhập giờ = 24:01 | C28: Pre-condition: + Đăng nhập bằng tài khoản ESS 'ess_test' (liên kết nhân viên 'Test Employee') + Đã có dữ liệu dự án (Time > Project Info): Customer 'CUS_Test'; Project 'PRJ_Alpha' (Activity: 'Development', 'Testing'); Project 'PRJ_Beta' (Activity: 'Support') + 'Test Employee' chưa có timesheet ở kỳ (tuần) hiện tại Step: 1. Chọn menu Time > Timesheets > My Timesheets 2. Click nút [Create Timesheet] 3. Tại Project Name gõ 'PRJ_A' và chọn 'PRJ_Alpha' từ danh sách gợi ý 4. Chọn Activity = 'Development' 5. Nhập '24:01' vào cột Mon 6. Click nút [Save] | D28: 6. Hiển thị lỗi validation tại ô; không lưu | E28: Đăng nhập với role ESS | F28: Untested
A29: =IF(OR(B29<>"",D29<>""),$B$2&"_"&TEXT(ROW()-8,"00"),"") -> TIME_CreateTimesheet_21 | B29: Kiểm tra giá trị rất lớn: nhập giờ = 100 | C29: Pre-condition: + Đăng nhập bằng tài khoản ESS 'ess_test' (liên kết nhân viên 'Test Employee') + Đã có dữ liệu dự án (Time > Project Info): Customer 'CUS_Test'; Project 'PRJ_Alpha' (Activity: 'Development', 'Testing'); Project 'PRJ_Beta' (Activity: 'Support') + 'Test Employee' chưa có timesheet ở kỳ (tuần) hiện tại Step: 1. Chọn menu Time > Timesheets > My Timesheets 2. Click nút [Create Timesheet] 3. Tại Project Name gõ 'PRJ_A' và chọn 'PRJ_Alpha' từ danh sách gợi ý 4. Chọn Activity = 'Development' 5. Nhập '100' vào cột Mon 6. Click nút [Save] | D29: 6. Hiển thị lỗi validation tại ô; không lưu; hệ thống không bị lỗi | E29: Đăng nhập với role ESS | F29: Untested
A30: =IF(OR(B30<>"",D30<>""),$B$2&"_"&TEXT(ROW()-8,"00"),"") -> TIME_CreateTimesheet_22 | B30: Kiểm tra biên phút hợp lệ: nhập giờ = 08:59 | C30: Pre-condition: + Đăng nhập bằng tài khoản ESS 'ess_test' (liên kết nhân viên 'Test Employee') + Đã có dữ liệu dự án (Time > Project Info): Customer 'CUS_Test'; Project 'PRJ_Alpha' (Activity: 'Development', 'Testing'); Project 'PRJ_Beta' (Activity: 'Support') + 'Test Employee' chưa có timesheet ở kỳ (tuần) hiện tại Step: 1. Chọn menu Time > Timesheets > My Timesheets 2. Click nút [Create Timesheet] 3. Tại Project Name gõ 'PRJ_A' và chọn 'PRJ_Alpha' từ danh sách gợi ý 4. Chọn Activity = 'Development' 5. Nhập '08:59' vào cột Mon 6. Click nút [Save] | D30: 6. Lưu thành công; ô Mon hiển thị 08:59 | E30: Đăng nhập với role ESS | F30: Untested
A31: =IF(OR(B31<>"",D31<>""),$B$2&"_"&TEXT(ROW()-8,"00"),"") -> TIME_CreateTimesheet_23 | B31: Kiểm tra vượt biên phút: nhập giờ = 08:60 | C31: Pre-condition: + Đăng nhập bằng tài khoản ESS 'ess_test' (liên kết nhân viên 'Test Employee') + Đã có dữ liệu dự án (Time > Project Info): Customer 'CUS_Test'; Project 'PRJ_Alpha' (Activity: 'Development', 'Testing'); Project 'PRJ_Beta' (Activity: 'Support') + 'Test Employee' chưa có timesheet ở kỳ (tuần) hiện tại Step: 1. Chọn menu Time > Timesheets > My Timesheets 2. Click nút [Create Timesheet] 3. Tại Project Name gõ 'PRJ_A' và chọn 'PRJ_Alpha' từ danh sách gợi ý 4. Chọn Activity = 'Development' 5. Nhập '08:60' vào cột Mon 6. Click nút [Save] | D31: 6. Hiển thị lỗi định dạng giờ tại ô; không lưu | E31: Đăng nhập với role ESS | F31: Untested | H31: Cần đối chiếu hành vi/thông báo thực tế trên OrangeHRM 5.x khi chạy test
A32: =IF(OR(B32<>"",D32<>""),$B$2&"_"&TEXT(ROW()-8,"00"),"") -> TIME_CreateTimesheet_24 | B32: Kiểm tra tổng giờ trong 1 ngày qua nhiều hàng vượt 24:00 (12:00 + 13:00) | C32: Pre-condition: + Đăng nhập bằng tài khoản ESS 'ess_test' (liên kết nhân viên 'Test Employee') + Đã có dữ liệu dự án (Time > Project Info): Customer 'CUS_Test'; Project 'PRJ_Alpha' (Activity: 'Development', 'Testing'); Project 'PRJ_Beta' (Activity: 'Support') + 'Test Employee' chưa có timesheet ở kỳ (tuần) hiện tại Step: 1. Chọn menu Time > Timesheets > My Timesheets 2. Click nút [Create Timesheet] 3. Tại Project Name gõ 'PRJ_A' và chọn 'PRJ_Alpha' từ danh sách gợi ý 4. Chọn Activity = 'Development' 5. Nhập '12:00' vào cột Mon 6. Click [Add Row] 7. Tại Project Name gõ 'PRJ_B' và chọn 'PRJ_Beta' từ danh sách gợi ý 8. Chọn Activity = 'Support' 9. Nhập '13:00' vào cột Mon 10. Click nút [Save] | D32: 10. Hệ thống không cho lưu hoặc cảnh báo tổng giờ/ngày vượt 24 giờ (theo nghiệp vụ hợp lý) | E32: Đăng nhập với role ESS | F32: Untested | H32: Cần xác nhận: OrangeHRM có thể chỉ kiểm tra giới hạn trên từng ô, không kiểm tra tổng/ngày
A33: =IF(OR(B33<>"",D33<>""),$B$2&"_"&TEXT(ROW()-8,"00"),"") -> TIME_CreateTimesheet_25 | B33: Kiểm tra comment dài đúng 250 ký tự | C33: Pre-condition: + Đăng nhập bằng tài khoản ESS 'ess_test' (liên kết nhân viên 'Test Employee') + Đã có dữ liệu dự án (Time > Project Info): Customer 'CUS_Test'; Project 'PRJ_Alpha' (Activity: 'Development', 'Testing'); Project 'PRJ_Beta' (Activity: 'Support') + 'Test Employee' chưa có timesheet ở kỳ (tuần) hiện tại Step: 1. Chọn menu Time > Timesheets > My Timesheets 2. Click nút [Create Timesheet] 3. Tại Project Name gõ 'PRJ_A' và chọn 'PRJ_Alpha' từ danh sách gợi ý 4. Chọn Activity = 'Development' 5. Nhập '08:00' vào cột Mon 6. Click biểu tượng comment ở ô Mon, nhập chuỗi 250 ký tự, xác nhận 7. Click nút [Save] | D33: 7. Lưu thành công; comment hiển thị đầy đủ 250 ký tự | E33: Đăng nhập với role ESS | F33: Untested | H33: Cần đối chiếu hành vi/thông báo thực tế trên OrangeHRM 5.x khi chạy test
A34: =IF(OR(B34<>"",D34<>""),$B$2&"_"&TEXT(ROW()-8,"00"),"") -> TIME_CreateTimesheet_26 | B34: Kiểm tra comment dài 251 ký tự (vượt biên) | C34: Pre-condition: + Đăng nhập bằng tài khoản ESS 'ess_test' (liên kết nhân viên 'Test Employee') + Đã có dữ liệu dự án (Time > Project Info): Customer 'CUS_Test'; Project 'PRJ_Alpha' (Activity: 'Development', 'Testing'); Project 'PRJ_Beta' (Activity: 'Support') + 'Test Employee' chưa có timesheet ở kỳ (tuần) hiện tại Step: 1. Chọn menu Time > Timesheets > My Timesheets 2. Click nút [Create Timesheet] 3. Tại Project Name gõ 'PRJ_A' và chọn 'PRJ_Alpha' từ danh sách gợi ý 4. Chọn Activity = 'Development' 5. Nhập '08:00' vào cột Mon 6. Click biểu tượng comment ở ô Mon, nhập chuỗi 251 ký tự, xác nhận 7. Click nút [Save] | D34: 7. Hiển thị lỗi vượt quá độ dài tối đa; không lưu comment | E34: Đăng nhập với role ESS | F34: Untested | H34: Cần đối chiếu hành vi/thông báo thực tế trên OrangeHRM 5.x khi chạy test
A35: =IF(OR(B35<>"",D35<>""),$B$2&"_"&TEXT(ROW()-8,"00"),"") -> TIME_CreateTimesheet_27 | B35: Kiểm tra lưu khi không chọn Project và Activity (đã nhập giờ) | C35: Pre-condition: + Đăng nhập bằng tài khoản ESS 'ess_test' (liên kết nhân viên 'Test Employee') + Đã có dữ liệu dự án (Time > Project Info): Customer 'CUS_Test'; Project 'PRJ_Alpha' (Activity: 'Development', 'Testing'); Project 'PRJ_Beta' (Activity: 'Support') + 'Test Employee' chưa có timesheet ở kỳ (tuần) hiện tại Step: 1. Chọn menu Time > Timesheets > My Timesheets 2. Click nút [Create Timesheet] 3. Nhập '08:00' vào cột Mon, để trống Project Name và Activity 4. Click nút [Save] | D35: 4. Hiển thị lỗi 'Required' tại Project Name và Activity; không lưu | E35: Đăng nhập với role ESS | F35: Untested
A36: =IF(OR(B36<>"",D36<>""),$B$2&"_"&TEXT(ROW()-8,"00"),"") -> TIME_CreateTimesheet_28 | B36: Kiểm tra lưu khi đã chọn Project nhưng bỏ trống Activity | C36: Pre-condition: + Đăng nhập bằng tài khoản ESS 'ess_test' (liên kết nhân viên 'Test Employee') + Đã có dữ liệu dự án (Time > Project Info): Customer 'CUS_Test'; Project 'PRJ_Alpha' (Activity: 'Development', 'Testing'); Project 'PRJ_Beta' (Activity: 'Support') + 'Test Employee' chưa có timesheet ở kỳ (tuần) hiện tại Step: 1. Chọn menu Time > Timesheets > My Timesheets 2. Click nút [Create Timesheet] 3. Chọn Project 'PRJ_Alpha', để trống Activity, nhập '08:00' vào cột Mon 4. Click nút [Save] | D36: 4. Hiển thị lỗi 'Required' tại Activity; không lưu | E36: Đăng nhập với role ESS | F36: Untested
A37: =IF(OR(B37<>"",D37<>""),$B$2&"_"&TEXT(ROW()-8,"00"),"") -> TIME_CreateTimesheet_29 | B37: Kiểm tra gõ Project Name nhưng không chọn từ danh sách gợi ý | C37: Pre-condition: + Đăng nhập bằng tài khoản ESS 'ess_test' (liên kết nhân viên 'Test Employee') + Đã có dữ liệu dự án (Time > Project Info): Customer 'CUS_Test'; Project 'PRJ_Alpha' (Activity: 'Development', 'Testing'); Project 'PRJ_Beta' (Activity: 'Support') + 'Test Employee' chưa có timesheet ở kỳ (tuần) hiện tại Step: 1. Chọn menu Time > Timesheets > My Timesheets 2. Click nút [Create Timesheet] 3. Gõ 'PRJ_Alp' vào Project Name (không chọn gợi ý), nhập '08:00' vào cột Mon 4. Click nút [Save] | D37: 4. Hiển thị lỗi 'Invalid' tại Project Name; không lưu | E37: Đăng nhập với role ESS | F37: Untested
A38: =IF(OR(B38<>"",D38<>""),$B$2&"_"&TEXT(ROW()-8,"00"),"") -> TIME_CreateTimesheet_30 | B38: Kiểm tra Project Name không tồn tại ('PRJ_NotExist') | C38: Pre-condition: + Đăng nhập bằng tài khoản ESS 'ess_test' (liên kết nhân viên 'Test Employee') + Đã có dữ liệu dự án (Time > Project Info): Customer 'CUS_Test'; Project 'PRJ_Alpha' (Activity: 'Development', 'Testing'); Project 'PRJ_Beta' (Activity: 'Support') + 'Test Employee' chưa có timesheet ở kỳ (tuần) hiện tại Step: 1. Chọn menu Time > Timesheets > My Timesheets 2. Click nút [Create Timesheet] 3. Gõ 'PRJ_NotExist' vào Project Name | D38: 3. Danh sách gợi ý hiển thị 'No Records Found'; Activity không có dữ liệu; Save báo lỗi 'Invalid' | E38: Đăng nhập với role ESS | F38: Untested
A39: =IF(OR(B39<>"",D39<>""),$B$2&"_"&TEXT(ROW()-8,"00"),"") -> TIME_CreateTimesheet_31 | B39: Kiểm tra nhập giờ là chữ ('abc') | C39: Pre-condition: + Đăng nhập bằng tài khoản ESS 'ess_test' (liên kết nhân viên 'Test Employee') + Đã có dữ liệu dự án (Time > Project Info): Customer 'CUS_Test'; Project 'PRJ_Alpha' (Activity: 'Development', 'Testing'); Project 'PRJ_Beta' (Activity: 'Support') + 'Test Employee' chưa có timesheet ở kỳ (tuần) hiện tại Step: 1. Chọn menu Time > Timesheets > My Timesheets 2. Click nút [Create Timesheet] 3. Tại Project Name gõ 'PRJ_A' và chọn 'PRJ_Alpha' từ danh sách gợi ý 4. Chọn Activity = 'Development' 5. Nhập 'abc' vào cột Mon 6. Click nút [Save] | D39: 6. Hiển thị lỗi định dạng giờ tại ô; không lưu | E39: Đăng nhập với role ESS | F39: Untested
A40: =IF(OR(B40<>"",D40<>""),$B$2&"_"&TEXT(ROW()-8,"00"),"") -> TIME_CreateTimesheet_32 | B40: Kiểm tra nhập giờ âm ('-1') | C40: Pre-condition: + Đăng nhập bằng tài khoản ESS 'ess_test' (liên kết nhân viên 'Test Employee') + Đã có dữ liệu dự án (Time > Project Info): Customer 'CUS_Test'; Project 'PRJ_Alpha' (Activity: 'Development', 'Testing'); Project 'PRJ_Beta' (Activity: 'Support') + 'Test Employee' chưa có timesheet ở kỳ (tuần) hiện tại Step: 1. Chọn menu Time > Timesheets > My Timesheets 2. Click nút [Create Timesheet] 3. Tại Project Name gõ 'PRJ_A' và chọn 'PRJ_Alpha' từ danh sách gợi ý 4. Chọn Activity = 'Development' 5. Nhập '-1' vào cột Mon 6. Click nút [Save] | D40: 6. Hiển thị lỗi định dạng/giá trị giờ tại ô; không lưu | E40: Đăng nhập với role ESS | F40: Untested
A41: =IF(OR(B41<>"",D41<>""),$B$2&"_"&TEXT(ROW()-8,"00"),"") -> TIME_CreateTimesheet_33 | B41: Kiểm tra nhập giờ chứa ký tự đặc biệt ('8@#') | C41: Pre-condition: + Đăng nhập bằng tài khoản ESS 'ess_test' (liên kết nhân viên 'Test Employee') + Đã có dữ liệu dự án (Time > Project Info): Customer 'CUS_Test'; Project 'PRJ_Alpha' (Activity: 'Development', 'Testing'); Project 'PRJ_Beta' (Activity: 'Support') + 'Test Employee' chưa có timesheet ở kỳ (tuần) hiện tại Step: 1. Chọn menu Time > Timesheets > My Timesheets 2. Click nút [Create Timesheet] 3. Tại Project Name gõ 'PRJ_A' và chọn 'PRJ_Alpha' từ danh sách gợi ý 4. Chọn Activity = 'Development' 5. Nhập '8@#' vào cột Mon 6. Click nút [Save] | D41: 6. Hiển thị lỗi định dạng giờ tại ô; không lưu | E41: Đăng nhập với role ESS | F41: Untested
A42: =IF(OR(B42<>"",D42<>""),$B$2&"_"&TEXT(ROW()-8,"00"),"") -> TIME_CreateTimesheet_34 | B42: Kiểm tra 2 hàng trùng cặp Project + Activity | C42: Pre-condition: + Đăng nhập bằng tài khoản ESS 'ess_test' (liên kết nhân viên 'Test Employee') + Đã có dữ liệu dự án (Time > Project Info): Customer 'CUS_Test'; Project 'PRJ_Alpha' (Activity: 'Development', 'Testing'); Project 'PRJ_Beta' (Activity: 'Support') + 'Test Employee' chưa có timesheet ở kỳ (tuần) hiện tại Step: 1. Chọn menu Time > Timesheets > My Timesheets 2. Click nút [Create Timesheet] 3. Tại Project Name gõ 'PRJ_A' và chọn 'PRJ_Alpha' từ danh sách gợi ý 4. Chọn Activity = 'Development' 5. Nhập '04:00' vào cột Mon 6. Click [Add Row] 7. Tại Project Name gõ 'PRJ_A' và chọn 'PRJ_Alpha' từ danh sách gợi ý 8. Chọn Activity = 'Development' 9. Nhập '04:00' vào cột Tue 10. Click nút [Save] | D42: 10. Hiển thị lỗi trùng dữ liệu (ví dụ: 'Duplicate Records Found'); không lưu | E42: Đăng nhập với role ESS | F42: Untested | H42: Cần đối chiếu hành vi/thông báo thực tế trên OrangeHRM 5.x khi chạy test
...

Sheet F08_TraCuuTimesheet
A2: Module Code | B2: TIME_SearchTimesheet | J2: Passed
A3: Test requirement | B3: F08. Tra cứu timesheet | J3: Failed
A4: Tester | B4: =Cover!G4 -> Nguyễn Thị Hồng Châu | J4: Blocked
A5: Passed | B5: Failed | C5: Untested | D5: Blocked | E5: Skipped | F5: Number of Test cases | J5: Untested
A6: =COUNTIF(F9:F77,"Passed") -> 0 | B6: =COUNTIF(F9:F77,"Failed") -> 0 | C6: =F6-E6-D6-B6-A6 -> 29 | D6: =COUNTIF(F9:F77,"Blocked") -> 0 | E6: =COUNTIF(F9:F77,"Skipped") -> 0 | F6: =COUNTA(A9:A77) -> 29 | J6: Skipped
A8: ID | B8: Test Case Description | C8: Test Case Procedure | D8: Expected Output | E8: Inter-test case Dependence | F8: Result | G8: Test date | H8: Note
A9: =IF(OR(B9<>"",D9<>""),$B$2&"_"&TEXT(ROW()-8,"00"),"") -> TIME_SearchTimesheet_01 | B9: Kiểm tra truy cập My Timesheets hiển thị timesheet kỳ hiện tại của chính nhân viên | C9: Pre-condition: + Đăng nhập bằng tài khoản ESS 'ess_test' (liên kết nhân viên 'Test Employee') + 'Test Employee' có timesheet kỳ hiện tại trạng thái 'Submitted' (PRJ_Alpha / Development, Mon–Fri 08:00) Step: 1. Chọn menu Time > Timesheets > My Timesheets | D9: 1. Trang My Timesheets hiển thị kỳ hiện tại, trạng thái và dữ liệu giờ của chính nhân viên đang đăng nhập | E9: Đăng nhập với role ESS | F9: Untested
A10: =IF(OR(B10<>"",D10<>""),$B$2&"_"&TEXT(ROW()-8,"00"),"") -> TIME_SearchTimesheet_02 | B10: Kiểm tra layout màn hình My Timesheets | C10: Pre-condition: + Đăng nhập bằng tài khoản ESS 'ess_test' (liên kết nhân viên 'Test Employee') + 'Test Employee' có timesheet kỳ hiện tại trạng thái 'Submitted' (PRJ_Alpha / Development, Mon–Fri 08:00) Step: 1. Chọn menu Time > Timesheets > My Timesheets | D10: 1. Hiển thị: kỳ timesheet và nút điều hướng kỳ trước/sau, trạng thái, bảng Project/Activity/7 ngày/Total, các nút thao tác theo trạng thái; căn chỉnh và nhãn đúng | E10: Đăng nhập với role ESS | F10: Untested | H10: Cần đối chiếu hành vi/thông báo thực tế trên OrangeHRM 5.x khi chạy test
A11: =IF(OR(B11<>"",D11<>""),$B$2&"_"&TEXT(ROW()-8,"00"),"") -> TIME_SearchTimesheet_03 | B11: Kiểm tra truy cập Employee Timesheets bằng tài khoản Admin | C11: Pre-condition: + Đăng nhập bằng tài khoản Admin (Admin / admin123) + 'Test Employee' có timesheet kỳ hiện tại trạng thái 'Submitted': PRJ_Alpha / Development, Mon–Fri mỗi ngày 08:00 (tổng 40:00) + 'Test Employee2' chưa có timesheet nào Step: 1. Chọn menu Time > Timesheets > Employee Timesheets | D11: 1. Màn hình Employee Timesheets hiển thị ô Employee Name (có gợi ý), nút [View] và danh sách timesheet chờ xử lý (nếu có) | E11: Đăng nhập với role Admin | F11: Untested
A12: =IF(OR(B12<>"",D12<>""),$B$2&"_"&TEXT(ROW()-8,"00"),"") -> TIME_SearchTimesheet_04 | B12: Kiểm tra layout màn hình Employee Timesheets | C12: Pre-condition: + Đăng nhập bằng tài khoản Admin (Admin / admin123) + 'Test Employee' có timesheet kỳ hiện tại trạng thái 'Submitted': PRJ_Alpha / Development, Mon–Fri mỗi ngày 08:00 (tổng 40:00) + 'Test Employee2' chưa có timesheet nào Step: 1. Chọn menu Time > Timesheets > Employee Timesheets | D12: 1. Nhãn, placeholder 'Type for hints...', nút [View] hiển thị đúng; căn chỉnh không bị vỡ | E12: Đăng nhập với role Admin | F12: Untested | H12: Cần đối chiếu hành vi/thông báo thực tế trên OrangeHRM 5.x khi chạy test
A13: =IF(OR(B13<>"",D13<>""),$B$2&"_"&TEXT(ROW()-8,"00"),"") -> TIME_SearchTimesheet_05 | B13: Kiểm tra danh sách timesheet chờ xử lý (Pending Action) hiển thị đúng | C13: Pre-condition: + Đăng nhập bằng tài khoản Admin (Admin / admin123) + 'Test Employee' có timesheet kỳ hiện tại trạng thái 'Submitted': PRJ_Alpha / Development, Mon–Fri mỗi ngày 08:00 (tổng 40:00) + 'Test Employee2' chưa có timesheet nào Step: 1. Chọn menu Time > Timesheets > Employee Timesheets | D13: 1. Danh sách có timesheet 'Test Employee' kỳ hiện tại (trạng thái Submitted) với tên nhân viên, kỳ, nút [View] | E13: Đăng nhập với role Admin | F13: Untested
A14: =IF(OR(B14<>"",D14<>""),$B$2&"_"&TEXT(ROW()-8,"00"),"") -> TIME_SearchTimesheet_06 | B14: Kiểm tra tìm theo tên nhân viên đầy đủ, chọn từ gợi ý rồi click [View] | C14: Pre-condition: + Đăng nhập bằng tài khoản Admin (Admin / admin123) + 'Test Employee' có timesheet kỳ hiện tại trạng thái 'Submitted': PRJ_Alpha / Development, Mon–Fri mỗi ngày 08:00 (tổng 40:00) + 'Test Employee2' chưa có timesheet nào Step: 1. Chọn menu Time > Timesheets > Employee Timesheets 2. Gõ 'Test Employee' vào Employee Name, chọn từ danh sách gợi ý 3. Click [View] | D14: 3. Hiển thị timesheet của 'Test Employee' (kỳ hiện tại, trạng thái Submitted, 5 ngày × 08:00, tổng 40:00) | E14: Đăng nhập với role Admin | F14: Untested
A15: =IF(OR(B15<>"",D15<>""),$B$2&"_"&TEXT(ROW()-8,"00"),"") -> TIME_SearchTimesheet_07 | B15: Kiểm tra gợi ý khi gõ một phần tên | C15: Pre-condition: + Đăng nhập bằng tài khoản Admin (Admin / admin123) + 'Test Employee' có timesheet kỳ hiện tại trạng thái 'Submitted': PRJ_Alpha / Development, Mon–Fri mỗi ngày 08:00 (tổng 40:00) + 'Test Employee2' chưa có timesheet nào Step: 1. Chọn menu Time > Timesheets > Employee Timesheets 2. Gõ 'Test' vào Employee Name | D15: 2. Danh sách gợi ý hiển thị các nhân viên có tên chứa 'Test' (gồm 'Test Employee', 'Test Employee2') | E15: Đăng nhập với role Admin | F15: Untested
A16: =IF(OR(B16<>"",D16<>""),$B$2&"_"&TEXT(ROW()-8,"00"),"") -> TIME_SearchTimesheet_08 | B16: Kiểm tra tìm kiếm không phân biệt chữ hoa/thường ('test employee') | C16: Pre-condition: + Đăng nhập bằng tài khoản Admin (Admin / admin123) + 'Test Employee' có timesheet kỳ hiện tại trạng thái 'Submitted': PRJ_Alpha / Development, Mon–Fri mỗi ngày 08:00 (tổng 40:00) + 'Test Employee2' chưa có timesheet nào Step: 1. Chọn menu Time > Timesheets > Employee Timesheets 2. Gõ 'test employee' (chữ thường), chọn từ gợi ý 3. Click [View] | D16: 3. Gợi ý vẫn hiển thị 'Test Employee'; [View] hiển thị đúng timesheet | E16: Đăng nhập với role Admin | F16: Untested
A17: =IF(OR(B17<>"",D17<>""),$B$2&"_"&TEXT(ROW()-8,"00"),"") -> TIME_SearchTimesheet_09 | B17: Kiểm tra tên có khoảng trắng ở đầu/cuối (' Test Employee ') | C17: Pre-condition: + Đăng nhập bằng tài khoản Admin (Admin / admin123) + 'Test Employee' có timesheet kỳ hiện tại trạng thái 'Submitted': PRJ_Alpha / Development, Mon–Fri mỗi ngày 08:00 (tổng 40:00) + 'Test Employee2' chưa có timesheet nào Step: 1. Chọn menu Time > Timesheets > Employee Timesheets 2. Gõ ' Test Employee ', chọn từ gợi ý (nếu có) 3. Click [View] | D17: 3. Hệ thống bỏ qua khoảng trắng thừa và hiển thị đúng timesheet, hoặc không báo lỗi hệ thống | E17: Đăng nhập với role Admin | F17: Untested | H17: Cần đối chiếu hành vi/thông báo thực tế trên OrangeHRM 5.x khi chạy test
A18: =IF(OR(B18<>"",D18<>""),$B$2&"_"&TEXT(ROW()-8,"00"),"") -> TIME_SearchTimesheet_10 | B18: Kiểm tra xem timesheet từ danh sách Pending Action | C18: Pre-condition: + Đăng nhập bằng tài khoản Admin (Admin / admin123) + 'Test Employee' có timesheet kỳ hiện tại trạng thái 'Submitted': PRJ_Alpha / Development, Mon–Fri mỗi ngày 08:00 (tổng 40:00) + 'Test Employee2' chưa có timesheet nào Step: 1. Chọn menu Time > Timesheets > Employee Timesheets 2. Tại danh sách Pending Action, click [View] của 'Test Employee' | D18: 2. Hiển thị chi tiết timesheet 'Test Employee', có thông tin kỳ, trạng thái, dữ liệu giờ | E18: Đăng nhập với role Admin | F18: Untested
A19: =IF(OR(B19<>"",D19<>""),$B$2&"_"&TEXT(ROW()-8,"00"),"") -> TIME_SearchTimesheet_11 | B19: Kiểm tra dữ liệu chi tiết timesheet khớp với dữ liệu đã nhập | C19: Pre-condition: + Đăng nhập bằng tài khoản Admin (Admin / admin123) + 'Test Employee' có timesheet kỳ hiện tại trạng thái 'Submitted': PRJ_Alpha / Development, Mon–Fri mỗi ngày 08:00 (tổng 40:00) + 'Test Employee2' chưa có timesheet nào Step: 1. Chọn menu Time > Timesheets > Employee Timesheets 2. Tìm và [View] timesheet của 'Test Employee' 3. Đối chiếu Project, Activity, giờ từng ngày, comment với dữ liệu gốc | D19: 3. Dữ liệu hiển thị hoàn toàn khớp dữ liệu đã nhập (Project, Activity, giờ, comment) | E19: TIME_SearchTimesheet_06 | F19: Untested
A20: =IF(OR(B20<>"",D20<>""),$B$2&"_"&TEXT(ROW()-8,"00"),"") -> TIME_SearchTimesheet_12 | B20: Kiểm tra tổng giờ theo ngày và tổng giờ cả tuần tính đúng | C20: Pre-condition: + Đăng nhập bằng tài khoản Admin (Admin / admin123) + 'Test Employee' có timesheet kỳ hiện tại trạng thái 'Submitted': PRJ_Alpha / Development, Mon–Fri mỗi ngày 08:00 (tổng 40:00) + 'Test Employee2' chưa có timesheet nào Step: 1. Chọn menu Time > Timesheets > Employee Timesheets 2. Tìm và [View] timesheet của 'Test Employee' | D20: 2. Total theo từng ngày = 08:00 (Mon–Fri), 00:00 (Sat, Sun); tổng tuần = 40:00 | E20: TIME_SearchTimesheet_06 | F20: Untested
A21: =IF(OR(B21<>"",D21<>""),$B$2&"_"&TEXT(ROW()-8,"00"),"") -> TIME_SearchTimesheet_13 | B21: Kiểm tra nhân viên chỉ xem được timesheet của chính mình ở My Timesheets | C21: Pre-condition: + Đăng nhập bằng tài khoản ESS 'ess_test' (liên kết nhân viên 'Test Employee') + 'Test Employee' có timesheet kỳ hiện tại trạng thái 'Submitted' (PRJ_Alpha / Development, Mon–Fri 08:00) Step: 1. Chọn menu Time > Timesheets > My Timesheets | D21: 1. Chỉ hiển thị timesheet của 'Test Employee'; không có dữ liệu của nhân viên khác | E21: Đăng nhập với role ESS | F21: Untested
A22: =IF(OR(B22<>"",D22<>""),$B$2&"_"&TEXT(ROW()-8,"00"),"") -> TIME_SearchTimesheet_14 | B22: Kiểm tra điều hướng sang kỳ (tuần) liền trước | C22: Pre-condition: + Đăng nhập bằng tài khoản ESS 'ess_test' (liên kết nhân viên 'Test Employee') + 'Test Employee' có timesheet kỳ hiện tại trạng thái 'Submitted' (PRJ_Alpha / Development, Mon–Fri 08:00) Step: 1. Chọn menu Time > Timesheets > My Timesheets 2. Click nút mũi tên kỳ trước | D22: 2. Hiển thị kỳ liền trước (lùi đúng 7 ngày), dữ liệu/trạng thái đúng với kỳ đó | E22: Đăng nhập với role ESS | F22: Untested
A23: =IF(OR(B23<>"",D23<>""),$B$2&"_"&TEXT(ROW()-8,"00"),"") -> TIME_SearchTimesheet_15 | B23: Kiểm tra điều hướng sang kỳ (tuần) liền sau | C23: Pre-condition: + Đăng nhập bằng tài khoản ESS 'ess_test' (liên kết nhân viên 'Test Employee') + 'Test Employee' có timesheet kỳ hiện tại trạng thái 'Submitted' (PRJ_Alpha / Development, Mon–Fri 08:00) Step: 1. Chọn menu Time > Timesheets > My Timesheets 2. Click nút mũi tên kỳ sau | D23: 2. Hiển thị kỳ liền sau (tiến đúng 7 ngày) hoặc chặn/disable nếu kỳ tương lai chưa cho tạo | E23: Đăng nhập với role ESS | F23: Untested | H23: Cần đối chiếu hành vi/thông báo thực tế trên OrangeHRM 5.x khi chạy test
A24: =IF(OR(B24<>"",D24<>""),$B$2&"_"&TEXT(ROW()-8,"00"),"") -> TIME_SearchTimesheet_16 | B24: Kiểm tra kỳ giao giữa hai năm (tuần chứa 31/12 và 01/01) | C24: Pre-condition: + Đăng nhập bằng tài khoản ESS 'ess_test' (liên kết nhân viên 'Test Employee') Step: 1. Chọn menu Time > Timesheets > My Timesheets 2. Điều hướng đến kỳ chứa ngày 31/12 và 01/01 (ví dụ 28/12 – 03/01) | D24: 2. Kỳ hiển thị đúng 7 ngày liên tục qua ranh giới năm; ngày/thứ không bị lệch | E24: Đăng nhập với role ESS | F24: Untested
A25: =IF(OR(B25<>"",D25<>""),$B$2&"_"&TEXT(ROW()-8,"00"),"") -> TIME_SearchTimesheet_17 | B25: Kiểm tra kỳ rất xa trong quá khứ (chưa có timesheet) | C25: Pre-condition: + Đăng nhập bằng tài khoản ESS 'ess_test' (liên kết nhân viên 'Test Employee') Step: 1. Chọn menu Time > Timesheets > My Timesheets 2. Click kỳ trước liên tiếp nhiều lần (khoảng 52 lần ≈ 1 năm) | D25: 2. Hệ thống không lỗi; kỳ không có timesheet hiển thị trạng thái trống / thông báo không có dữ liệu | E25: Đăng nhập với role ESS | F25: Untested | H25: Cần đối chiếu hành vi/thông báo thực tế trên OrangeHRM 5.x khi chạy test
A26: =IF(OR(B26<>"",D26<>""),$B$2&"_"&TEXT(ROW()-8,"00"),"") -> TIME_SearchTimesheet_18 | B26: Kiểm tra nhập 1 ký tự vào Employee Name (độ dài tối thiểu) | C26: Pre-condition: + Đăng nhập bằng tài khoản Admin (Admin / admin123) + 'Test Employee' có timesheet kỳ hiện tại trạng thái 'Submitted': PRJ_Alpha / Development, Mon–Fri mỗi ngày 08:00 (tổng 40:00) + 'Test Employee2' chưa có timesheet nào Step: 1. Chọn menu Time > Timesheets > Employee Timesheets 2. Gõ 'T' vào Employee Name | D26: 2. Danh sách gợi ý hiển thị các nhân viên phù hợp hoặc 'No Records Found'; không lỗi hệ thống | E26: Đăng nhập với role Admin | F26: Untested
A27: =IF(OR(B27<>"",D27<>""),$B$2&"_"&TEXT(ROW()-8,"00"),"") -> TIME_SearchTimesheet_19 | B27: Kiểm tra nhập chuỗi rất dài (≥ 100 ký tự) vào Employee Name | C27: Pre-condition: + Đăng nhập bằng tài khoản Admin (Admin / admin123) + 'Test Employee' có timesheet kỳ hiện tại trạng thái 'Submitted': PRJ_Alpha / Development, Mon–Fri mỗi ngày 08:00 (tổng 40:00) + 'Test Employee2' chưa có timesheet nào Step: 1. Chọn menu Time > Timesheets > Employee Timesheets 2. Gõ chuỗi 100+ ký tự 'a' vào Employee Name 3. Click [View] | D27: 3. Không có gợi ý ('No Records Found'); [View] báo 'Invalid'/giới hạn độ dài; hệ thống không bị lỗi | E27: Đăng nhập với role Admin | F27: Untested | H27: Cần đối chiếu hành vi/thông báo thực tế trên OrangeHRM 5.x khi chạy test
A28: =IF(OR(B28<>"",D28<>""),$B$2&"_"&TEXT(ROW()-8,"00"),"") -> TIME_SearchTimesheet_20 | B28: Kiểm tra click [View] khi để trống Employee Name | C28: Pre-condition: + Đăng nhập bằng tài khoản Admin (Admin / admin123) + 'Test Employee' có timesheet kỳ hiện tại trạng thái 'Submitted': PRJ_Alpha / Development, Mon–Fri mỗi ngày 08:00 (tổng 40:00) + 'Test Employee2' chưa có timesheet nào Step: 1. Chọn menu Time > Timesheets > Employee Timesheets 2. Để trống Employee Name 3. Click [View] | D28: 3. Hiển thị lỗi 'Required' tại Employee Name; không chuyển trang | E28: Đăng nhập với role Admin | F28: Untested
A29: =IF(OR(B29<>"",D29<>""),$B$2&"_"&TEXT(ROW()-8,"00"),"") -> TIME_SearchTimesheet_21 | B29: Kiểm tra tên nhân viên không tồn tại ('Nobody Existing') | C29: Pre-condition: + Đăng nhập bằng tài khoản Admin (Admin / admin123) + 'Test Employee' có timesheet kỳ hiện tại trạng thái 'Submitted': PRJ_Alpha / Development, Mon–Fri mỗi ngày 08:00 (tổng 40:00) + 'Test Employee2' chưa có timesheet nào Step: 1. Chọn menu Time > Timesheets > Employee Timesheets 2. Gõ 'Nobody Existing' vào Employee Name 3. Click [View] | D29: 3. Gợi ý hiển thị 'No Records Found'; click [View] báo lỗi 'Invalid'; không hiển thị timesheet | E29: Đăng nhập với role Admin | F29: Untested
A30: =IF(OR(B30<>"",D30<>""),$B$2&"_"&TEXT(ROW()-8,"00"),"") -> TIME_SearchTimesheet_22 | B30: Kiểm tra gõ đúng tên nhưng không chọn từ danh sách gợi ý | C30: Pre-condition: + Đăng nhập bằng tài khoản Admin (Admin / admin123) + 'Test Employee' có timesheet kỳ hiện tại trạng thái 'Submitted': PRJ_Alpha / Development, Mon–Fri mỗi ngày 08:00 (tổng 40:00) + 'Test Employee2' chưa có timesheet nào Step: 1. Chọn menu Time > Timesheets > Employee Timesheets 2. Gõ 'Test Employee' nhưng không click chọn gợi ý 3. Click [View] | D30: 3. Hiển thị lỗi 'Invalid' tại Employee Name; không chuyển trang | E30: Đăng nhập với role Admin | F30: Untested
A31: =IF(OR(B31<>"",D31<>""),$B$2&"_"&TEXT(ROW()-8,"00"),"") -> TIME_SearchTimesheet_23 | B31: Kiểm tra nhập ký tự đặc biệt '@#$%^&*' vào Employee Name | C31: Pre-condition: + Đăng nhập bằng tài khoản Admin (Admin / admin123) + 'Test Employee' có timesheet kỳ hiện tại trạng thái 'Submitted': PRJ_Alpha / Development, Mon–Fri mỗi ngày 08:00 (tổng 40:00) + 'Test Employee2' chưa có timesheet nào Step: 1. Chọn menu Time > Timesheets > Employee Timesheets 2. Gõ '@#$%^&*' vào Employee Name 3. Click [View] | D31: 3. 'No Records Found' / lỗi 'Invalid'; không có lỗi hệ thống | E31: Đăng nhập với role Admin | F31: Untested
A32: =IF(OR(B32<>"",D32<>""),$B$2&"_"&TEXT(ROW()-8,"00"),"") -> TIME_SearchTimesheet_24 | B32: Kiểm tra nhân viên chưa có timesheet ('Test Employee2') | C32: Pre-condition: + Đăng nhập bằng tài khoản Admin (Admin / admin123) + 'Test Employee' có timesheet kỳ hiện tại trạng thái 'Submitted': PRJ_Alpha / Development, Mon–Fri mỗi ngày 08:00 (tổng 40:00) + 'Test Employee2' chưa có timesheet nào Step: 1. Chọn menu Time > Timesheets > Employee Timesheets 2. Chọn 'Test Employee2' từ gợi ý 3. Click [View] | D32: 3. Hiển thị thông báo không có timesheet (ví dụ 'No Timesheets Found') hoặc timesheet trống; không lỗi hệ thống | E32: Đăng nhập với role Admin | F32: Untested | H32: Cần đối chiếu hành vi/thông báo thực tế trên OrangeHRM 5.x khi chạy test
A33: =IF(OR(B33<>"",D33<>""),$B$2&"_"&TEXT(ROW()-8,"00"),"") -> TIME_SearchTimesheet_25 | B33: Kiểm tra SQL Injection tại Employee Name: ' OR 1=1 -- | C33: Pre-condition: + Đăng nhập bằng tài khoản Admin (Admin / admin123) + 'Test Employee' có timesheet kỳ hiện tại trạng thái 'Submitted': PRJ_Alpha / Development, Mon–Fri mỗi ngày 08:00 (tổng 40:00) + 'Test Employee2' chưa có timesheet nào Step: 1. Chọn menu Time > Timesheets > Employee Timesheets 2. Gõ "' OR 1=1 --" vào Employee Name 3. Click [View] | D33: 3. Không lỗi SQL/hệ thống; không lộ dữ liệu; hiển thị 'No Records Found' / 'Invalid' | E33: Đăng nhập với role Admin | F33: Untested
A34: =IF(OR(B34<>"",D34<>""),$B$2&"_"&TEXT(ROW()-8,"00"),"") -> TIME_SearchTimesheet_26 | B34: Kiểm tra XSS tại Employee Name: <script>alert(1)</script> | C34: Pre-condition: + Đăng nhập bằng tài khoản Admin (Admin / admin123) + 'Test Employee' có timesheet kỳ hiện tại trạng thái 'Submitted': PRJ_Alpha / Development, Mon–Fri mỗi ngày 08:00 (tổng 40:00) + 'Test Employee2' chưa có timesheet nào Step: 1. Chọn menu Time > Timesheets > Employee Timesheets 2. Gõ <script>alert(1)</script> vào Employee Name 3. Click [View] | D34: 3. Script không được thực thi; hiển thị 'No Records Found' / 'Invalid' | E34: Đăng nhập với role Admin | F34: Untested
A35: =IF(OR(B35<>"",D35<>""),$B$2&"_"&TEXT(ROW()-8,"00"),"") -> TIME_SearchTimesheet_27 | B35: Kiểm tra ESS (không phải supervisor) không truy cập được Employee Timesheets | C35: Pre-condition: + Đăng nhập bằng tài khoản ESS 'ess_test' (liên kết nhân viên 'Test Employee') (không có cấp dưới) + 'Test Employee' có timesheet kỳ hiện tại trạng thái 'Submitted' (PRJ_Alpha / Development, Mon–Fri 08:00) Step: 1. Kiểm tra menu Time > Timesheets 2. Truy cập trực tiếp URL trang Employee Timesheets | D35: 2. Menu chỉ có 'My Timesheets' (hoặc không có Employee Timesheets); truy cập URL bị từ chối/chuyển hướng | E35: Đăng nhập với role ESS | F35: Untested | H35: Cần đối chiếu hành vi/thông báo thực tế trên OrangeHRM 5.x khi chạy test
A36: =IF(OR(B36<>"",D36<>""),$B$2&"_"&TEXT(ROW()-8,"00"),"") -> TIME_SearchTimesheet_28 | B36: Kiểm tra ESS không xem được timesheet nhân viên khác bằng cách đổi ID trên URL | C36: Pre-condition: + Đăng nhập bằng tài khoản ESS 'ess_test' (liên kết nhân viên 'Test Employee') + 'Test Employee' có timesheet kỳ hiện tại trạng thái 'Submitted' (PRJ_Alpha / Development, Mon–Fri 08:00) Step: 1. Chọn menu Time > Timesheets > My Timesheets 2. Sao chép URL, thay ID nhân viên bằng ID của nhân viên khác, truy cập URL | D36: 2. Hệ thống từ chối truy cập hoặc quay về My Timesheets; không hiển thị dữ liệu của nhân viên khác | E36: Đăng nhập với role ESS | F36: Untested | H36: Cần đối chiếu hành vi/thông báo thực tế trên OrangeHRM 5.x khi chạy test
A37: =IF(OR(B37<>"",D37<>""),$B$2&"_"&TEXT(ROW()-8,"00"),"") -> TIME_SearchTimesheet_29 | B37: Kiểm tra truy cập trang Employee Timesheets khi chưa đăng nhập | C37: Pre-condition: + Chưa đăng nhập; biết URL trang Employee Timesheets Step: 1. Mở trình duyệt mới (chưa đăng nhập), truy cập trực tiếp URL Employee Timesheets | D37: 1. Chuyển hướng về trang Login; không hiển thị dữ liệu | F37: Untested

Sheet F09_GuiVaXuLy
A2: Module Code | B2: TIME_SubmitProcess | J2: Passed
A3: Test requirement | B3: F09. Gửi và xử lý timesheet | J3: Failed
A4: Tester | B4: =Cover!G4 -> Nguyễn Thị Hồng Châu | J4: Blocked
A5: Passed | B5: Failed | C5: Untested | D5: Blocked | E5: Skipped | F5: Number of Test cases | J5: Untested
A6: =COUNTIF(F9:F84,"Passed") -> 0 | B6: =COUNTIF(F9:F84,"Failed") -> 0 | C6: =F6-E6-D6-B6-A6 -> 36 | D6: =COUNTIF(F9:F84,"Blocked") -> 0 | E6: =COUNTIF(F9:F84,"Skipped") -> 0 | F6: =COUNTA(A9:A84) -> 36 | J6: Skipped
A8: ID | B8: Test Case Description | C8: Test Case Procedure | D8: Expected Output | E8: Inter-test case Dependence | F8: Result | G8: Test date | H8: Note
