Workbook
Name LOCAL_DATE_SEPARATOR: #REF!
Name LOCAL_SECOND_FORMAT: #REF!
Name LOCAL_MONTH_FORMAT: #REF!
Name LOCAL_TIME_SEPARATOR: #REF!
Name ACTION: #REF!
Name LOCAL_YEAR_FORMAT: #REF!
Name LOCAL_MINUTE_FORMAT: #REF!
Name LOCAL_HOUR_FORMAT: #REF!
Name LOCAL_DAY_FORMAT: #REF!

Sheet Cover
B2: TEST CASE
B4: Project Name | C4: OrangeHRM – Module Admin | F4: Creator | G4: Ngô Thanh Vy
B5: Project Code | C5: OHRM_ADM | F5: Reviewer/Approver | G5: Trần Thị Thanh Nga
B6: Document Code | C6: OHRM_ADM_TestCase_V1.0 | F6: Issue Date | G6: 46322
F7: Version | G7: 1.0
B10: Record of change
B11: Effective Date | C11: Version | D11: Change Item | E11: *A,D,M | F11: Change description | G11: Reference
B12: 46322 | C12: 1.0 | D12: All | E12: A | F12: Khởi tạo bộ tài liệu Thiết kế và Chi tiết Test Case cho 3 chức năng của module Admin: 1. Tạo tài khoản hệ thống (Admin_User_Create) 2. Tìm kiếm và chỉnh sửa tài khoản (Admin_User_Search_Edit) 3. Quản lý danh mục hệ thống (Admin_System_Catalog) | G12: REQ-ADM-01 Software Requirement Specification

Sheet Test case List
D1: TEST CASE LIST
B3: Project Name | D3: =Cover!C4 -> OrangeHRM – Module Admin
B4: Project Code | D4: =Cover!C5 -> OHRM_ADM
B5: Test Environment Setup Description | D5: 1. Application Under Test (AUT): Website OrangeHRM Live Demo – module Admin (https://opensource-demo.orangehrmlive.com/web/index.php/auth/login). 2. Web Browser: Google Chrome (bản cập nhật ổn định); có thể kiểm tra bổ sung Edge nếu nằm trong phạm vi. 3. Operating System: Windows 10/11 64-bit. 4. Screen Resolution: 1920×1080 (Desktop); responsive/mobile chỉ kiểm tra nếu thuộc phạm vi. 5. Automation Testing Tool: Chưa cố định; có thể dùng kiểm thử thủ công và công cụ được nhóm thống nhất. 6. Network Environment: Kết nối Internet ổn định; ghi nhận lỗi mạng nếu ảnh hưởng kết quả. 7. Test Data & Accounts: Tài khoản quản trị demo Admin / admin123 (hiển thị trên trang đăng nhập); dữ liệu thử dùng tiền tố "g10tv5_" (Username) và "G10TV5" (danh mục), mật khẩu thử Test@12345. 8. Safety: Demo dùng chung và được reset định kỳ; không sửa/xóa/vô hiệu hóa tài khoản Admin mặc định và dữ liệu không do nhóm tạo; không nhập dữ liệu cá nhân thật; dọn dữ liệu kiểm thử sau khi chạy.
B8: No | C8: Function Name | D8: Sheet Name | E8: Description | F8: Pre-Condition
B9: 1 | C9: Admin_User_Create | D9: Tạo tài khoản hệ thống | E9: Điều hướng module Admin, mở form Add User, nhập User Role/Employee Name/Status/Username/Password; kiểm tra tạo hợp lệ, bắt buộc, giá trị biên, trùng lặp, bảo mật và phân quyền. | F9: Đã đăng nhập Admin/admin123 trên OrangeHRM Live Demo; có nhân viên chưa được gán tài khoản; dữ liệu thử dùng tiền tố "g10tv5_".
B10: 2 | C10: Admin_User_Search_Edit | D10: Tìm kiếm và chỉnh sửa tài khoản | E10: Tìm kiếm tài khoản theo Username/User Role/Employee Name/Status ,Reset, sắp xếp; mở form Edit User, cập nhật, kiểm tra dữ liệu không hợp lệ và xóa tài khoản kiểm thử. | F10: Đã đăng nhập Admin; đã có các tài khoản kiểm thử từ chức năng F13 (g10tv5_admin01, g10tv5_ess01, g10tv5_off01).
B11: 3 | C11: Admin_System_Catalog | D11: Quản lý danh mục hệ thống | E11: Quản lý các danh mục dùng chung (Job Titles, Employment Status, Skills, Nationalities): hiển thị, thêm, sửa, xóa, kiểm tra bắt buộc, trùng tên, giá trị biên và tệp đính kèm. | F11: Đã đăng nhập Admin; có quyền truy cập menu Admin > Job / Qualifications / Nationalities; có tệp PDF thử (<1MB và >1MB) và tệp .jpg/.exe.

Sheet TestDesign
A1: Requirement Level 1 | B1: Requirement Level 2 | C1: Requirement Level 3 | D1: Test Criteria | E1: Test Type | F1: Note
A2: 1. Tạo tài khoản hệ thống | B2: 1.1. Điều hướng & Hiển thị form | C2: Đăng nhập & Điều hướng | D2: Kiểm tra đăng nhập Admin, truy cập module Admin > User Management > Users và mở form [+ Add] | E2: Function
C3: Hiển thị form | D3: Kiểm tra bố cục form Add User, giá trị mặc định và danh sách lựa chọn của User Role, Status | E3: GUI
C4: Hủy thao tác | D4: Kiểm tra nút [Cancel] hủy việc tạo tài khoản và không lưu dữ liệu | E4: Function
B5: 1.2. Tạo tài khoản hợp lệ | C5: Tạo theo vai trò & trạng thái | D5: Kiểm tra tạo tài khoản thành công với các tổ hợp User Role (Admin/ESS) và Status (Enabled/Disabled) | E5: Function
C6: Hiệu lực tài khoản sau khi tạo | D6: Kiểm tra tài khoản Enabled đăng nhập được, tài khoản Disabled bị chặn đăng nhập | E6: Function
B7: 1.3. Trường Employee Name | C7: Gợi ý nhân viên | D7: Kiểm tra gợi ý (autocomplete) khi nhập Employee Name và chọn nhân viên từ danh sách | E7: Function
C8: Employee không hợp lệ | D8: Kiểm tra nhập nhân viên không tồn tại và nhân viên đã có tài khoản hệ thống | E8: Function
B9: 1.4. Kiểm tra trường bắt buộc | C9: Bỏ trống dữ liệu | D9: Kiểm tra hệ thống báo lỗi "Required" khi bỏ trống các trường bắt buộc | E9: Function
B10: 1.5. Kiểm tra trường Username | C10: Trùng lặp Username | D10: Kiểm tra hệ thống chặn Username đã tồn tại (kể cả khác chữ hoa/thường) | E10: Function
C11: Giá trị biên độ dài Username | D11: Kiểm tra giá trị biên độ dài Username: 4 / 5 / 40 / 41 ký tự (cho phép 5-40 ký tự) | E11: Function
C12: Ký tự đặc biệt & bảo mật | D12: Kiểm tra hệ thống xử lý an toàn khi nhập mã script vào trường Username (XSS) | E12: Security
B13: 1.6. Kiểm tra trường Password | C13: Độ dài mật khẩu | D13: Kiểm tra giá trị biên độ dài Password: 6 / 7 / 65 ký tự (cho phép 7-64 ký tự) | E13: Function
C14: Độ mạnh mật khẩu | D14: Kiểm tra hệ thống áp dụng chính sách độ mạnh mật khẩu (bắt buộc có chữ số) | E14: Function
C15: Xác nhận mật khẩu | D15: Kiểm tra Confirm Password phải trùng khớp với Password | E15: Function
C16: Hiển thị & bảo mật mật khẩu | D16: Kiểm tra mật khẩu được che khi nhập và thanh đánh giá độ mạnh mật khẩu | E16: Security
B17: 1.7. Phân quyền truy cập | C17: Giới hạn quyền của ESS | D17: Kiểm tra tài khoản User Role "ESS" không truy cập được chức năng quản trị tài khoản | E17: Security
A19: 2. Tìm kiếm và chỉnh sửa tài khoản | B19: 2.1. Màn hình System Users | C19: Hiển thị màn hình | D19: Kiểm tra bố cục khu vực tìm kiếm, bảng kết quả và danh sách mặc định | E19: GUI
B20: 2.2. Tìm kiếm theo từng tiêu chí | C20: Tìm theo Username | D20: Kiểm tra tìm kiếm theo Username: khớp chính xác và khớp một phần (không phân biệt hoa/thường) | E20: Function
C21: Tìm theo User Role | D21: Kiểm tra lọc danh sách theo User Role (Admin, ESS) | E21: Function
C22: Tìm theo Employee Name | D22: Kiểm tra tìm kiếm theo Employee Name chọn từ danh sách gợi ý | E22: Function
C23: Tìm theo Status | D23: Kiểm tra lọc danh sách theo Status (Enabled, Disabled) | E23: Function
C24: Kết hợp nhiều điều kiện | D24: Kiểm tra tìm kiếm kết hợp nhiều tiêu chí (điều kiện AND) | E24: Function
B25: 2.3. Tìm kiếm không có kết quả & dữ liệu không hợp lệ | C25: Không có kết quả | D25: Kiểm tra thông báo khi không tìm thấy bản ghi phù hợp | E25: Function
C26: Dữ liệu không hợp lệ | D26: Kiểm tra hệ thống xử lý an toàn với dữ liệu nhập sai/độc hại khi tìm kiếm | E26: Function
B27: 2.4. Đặt lại bộ lọc & Sắp xếp | C27: Đặt lại bộ lọc | D27: Kiểm tra nút [Reset] xóa điều kiện lọc và tải lại toàn bộ danh sách | E27: Function
C28: Sắp xếp danh sách | D28: Kiểm tra sắp xếp danh sách theo cột Username tăng dần/giảm dần | E28: Function
B29: 2.5. Mở form chỉnh sửa | C29: Mở form Edit User | D29: Kiểm tra click icon [Edit] mở form Edit User với dữ liệu hiện tại của tài khoản | E29: Function
B30: 2.6. Cập nhật thông tin hợp lệ | C30: Cập nhật vai trò & trạng thái | D30: Kiểm tra cập nhật User Role và Status của tài khoản | E30: Function
C31: Cập nhật Username & Password | D31: Kiểm tra đổi Username và đổi mật khẩu cho tài khoản đã có | E31: Function
B32: 2.7. Kiểm tra dữ liệu khi chỉnh sửa | C32: Kiểm tra Username | D32: Kiểm tra validate Username khi chỉnh sửa: trùng lặp, độ dài tối thiểu, bỏ trống | E32: Function
C33: Kiểm tra Employee Name & Password | D33: Kiểm tra validate Employee Name và Password khi chỉnh sửa | E33: Function
C34: Hủy chỉnh sửa | D34: Kiểm tra nút [Cancel] không lưu thay đổi khi chỉnh sửa | E34: Function
B35: 2.8. Xóa tài khoản kiểm thử | C35: Xóa tài khoản | D35: Kiểm tra hộp thoại xác nhận xóa và xóa thành công tài khoản kiểm thử để dọn dữ liệu | E35: Function
A37: 3. Quản lý danh mục hệ thống | B37: 3.1. Job Titles - Điều hướng & Hiển thị | C37: Điều hướng | D37: Kiểm tra truy cập danh mục Job Titles từ menu Admin > Job | E37: Function
C38: Hiển thị form | D38: Kiểm tra bố cục form Add Job Title | E38: GUI
B39: 3.2. Job Titles - Thêm mới | C39: Thêm mới hợp lệ | D39: Kiểm tra thêm Job Title thành công với dữ liệu tối thiểu, dữ liệu đầy đủ và có tệp đính kèm | E39: Function
C40: Dữ liệu không hợp lệ | D40: Kiểm tra validate Job Title: bỏ trống, trùng tên, giá trị biên 100/101 ký tự, tệp quá dung lượng/sai định dạng | E40: Function
C41: Hủy thao tác | D41: Kiểm tra nút [Cancel] không lưu dữ liệu khi thêm mới | E41: Function
B42: 3.3. Job Titles - Sửa & Xóa | C42: Chỉnh sửa Job Title | D42: Kiểm tra cập nhật Job Title và chặn đổi thành tên đã tồn tại | E42: Function
...

Sheet Tạo tài khoản hệ thống
A2: Module Code | B2: Admin – Quản trị hệ thống | I2: Pass
A3: Test requirement | B3: F13. Tạo tài khoản hệ thống | I3: Fail
A4: Req ID | B4: REQ-ADM-01 | I4: Pending
A5: Tester | B5: Ngô Thanh Vy | I5: Untested
A6: Pass | B6: Fail | C6: Untested | D6: Pending | E6: N/A | F6: Number of Test cases | I6: N/A
A7: =COUNTIF($F$14:$F$63,"Pass") -> 29 | B7: =COUNTIF($F$14:$F$63,"Fail") -> 0 | C7: =COUNTIF($F$14:$F$63,"Untested") -> 0 | D7: =COUNTIF($F$14:$F$63,"Pending") -> 0 | E7: =COUNTIF($F$14:$F$63,"N/A") -> 0 | F7: =COUNTIF($A$14:$A$63,"TC_*") -> 29 | I7: Cancel
A9: Test Case ID | B9: Test Case Description | C9: Test Case Procedure | D9: Expected Output | E9: Inter-test case Dependence | F9: Result | G9: Test date | H9: Priority | I9: Note
A10: Chrome
B12: 1.1. Điều hướng & Hiển thị form
B13: Đăng nhập & Điều hướng
A14: TC_ADM_CREATE_001 | B14: Kiểm tra đăng nhập bằng tài khoản Admin và truy cập module Admin | C14: 1. Truy cập https://opensource-demo.orangehrmlive.com. 2. Nhập Username "Admin", Password "admin123". 3. Click [Login]. 4. Click menu "Admin" ở thanh menu bên trái. | D14: Đăng nhập thành công và chuyển đến Dashboard. Sau khi chọn menu Admin, hệ thống hiển thị trang Admin > User Management > Users với tiêu đề "System Users" và danh sách tài khoản. | F14: Pass | G14: 46322 | H14: High | I14: Positive
A15: TC_ADM_CREATE_002 | B15: Kiểm tra click nút [+ Add] mở form thêm tài khoản hệ thống | C15: 1. Tại trang System Users, click nút [+ Add]. 2. Quan sát phản hồi của hệ thống. | D15: Hệ thống chuyển sang trang Add User (/admin/saveSystemUser), hiển thị tiêu đề "Add User"; trang tải đầy đủ, không phát sinh lỗi. | E15: TC_ADM_CREATE_001 | F15: Pass | G15: 46322 | H15: High | I15: Positive
B16: Hiển thị form
A17: TC_ADM_CREATE_003 | B17: Kiểm tra bố cục giao diện form Add User | C17: Quan sát toàn bộ form Add User. | D17: Hiển thị đầy đủ các trường: User Role*, Employee Name*, Status*, Username*, Password*, Confirm Password*; có chú thích "* Required"; có nút [Cancel] và [Save]. Các trường bắt buộc có dấu *, bố cục căn chỉnh đúng thiết kế. | E17: TC_ADM_CREATE_002 | F17: Pass | G17: 46322 | H17: Medium | I17: Positive
A18: TC_ADM_CREATE_004 | B18: Kiểm tra giá trị mặc định và danh sách lựa chọn của dropdown User Role, Status | C18: 1. Quan sát giá trị mặc định của các trường. 2. Click lần lượt dropdown [User Role] và [Status] để xem danh sách lựa chọn. | D18: User Role và Status mặc định "-- Select --"; Employee Name hiển thị placeholder "Type for hints..."; Username, Password, Confirm Password để trống. [User Role] gồm: Admin, ESS; [Status] gồm: Enabled, Disabled. | E18: TC_ADM_CREATE_002 | F18: Pass | G18: 46322 | H18: Low | I18: Positive
B19: Hủy thao tác
A20: TC_ADM_CREATE_005 | B20: Kiểm tra nút [Cancel] hủy việc tạo tài khoản | C20: 1. Tại form Add User, nhập Username "g10tv5_cancel" và chọn User Role "ESS". 2. Click [Cancel]. 3. Tại trang System Users, tìm kiếm Username "g10tv5_cancel". | D20: Hệ thống quay lại trang System Users, không hiển thị thông báo lưu. Tìm kiếm không có kết quả ("No Records Found") - tài khoản không được tạo. | E20: TC_ADM_CREATE_002 | F20: Pass | G20: 46322 | H20: Low | I20: Positive
B21: 1.2. Tạo tài khoản hợp lệ
B22: Tạo theo vai trò & trạng thái
A23: TC_ADM_CREATE_006 | B23: Kiểm tra tạo tài khoản User Role "Admin", Status "Enabled" với dữ liệu hợp lệ | C23: 1. Tại form Add User, chọn User Role "Admin". 2. Nhập Employee Name: gõ ký tự đầu và chọn 1 nhân viên chưa có tài khoản trong danh sách gợi ý. 3. Chọn Status "Enabled". 4. Nhập Username "g10tv5_admin01", Password "Test@12345", Confirm Password "Test@12345". 5. Click [Save]. | D23: Hiển thị thông báo "Successfully Saved"; hệ thống quay lại trang System Users; tài khoản "g10tv5_admin01" xuất hiện trong danh sách với User Role "Admin", Status "Enabled" và đúng Employee Name đã chọn. | E23: TC_ADM_CREATE_003 | F23: Pass | G23: 46322 | H23: High | I23: Positive
A24: TC_ADM_CREATE_007 | B24: Kiểm tra tạo tài khoản User Role "ESS", Status "Enabled" với dữ liệu hợp lệ | C24: 1. Tại form Add User, chọn User Role "ESS". 2. Chọn 1 nhân viên chưa có tài khoản ở Employee Name. 3. Chọn Status "Enabled". 4. Nhập Username "g10tv5_ess01", Password "Test@12345", Confirm Password "Test@12345". 5. Click [Save]. | D24: Hiển thị thông báo "Successfully Saved"; tài khoản "g10tv5_ess01" xuất hiện trong danh sách với User Role "ESS", Status "Enabled". | E24: TC_ADM_CREATE_003 | F24: Pass | G24: 46322 | H24: High | I24: Positive
A25: TC_ADM_CREATE_008 | B25: Kiểm tra tạo tài khoản với Status "Disabled" | C25: 1. Tại form Add User, chọn User Role "ESS", chọn 1 nhân viên chưa có tài khoản. 2. Chọn Status "Disabled". 3. Nhập Username "g10tv5_off01", Password "Test@12345", Confirm Password "Test@12345". 4. Click [Save]. | D25: Hiển thị thông báo "Successfully Saved"; tài khoản "g10tv5_off01" xuất hiện trong danh sách với Status "Disabled". | E25: TC_ADM_CREATE_003 | F25: Pass | G25: 46322 | H25: Medium | I25: Positive
B26: Hiệu lực tài khoản sau khi tạo
A27: TC_ADM_CREATE_009 | B27: Kiểm tra đăng nhập bằng tài khoản ESS vừa tạo (Status "Enabled") | C27: 1. Đăng xuất (click tên người dùng góc phải > Logout). 2. Đăng nhập với Username "g10tv5_ess01", Password "Test@12345". | D27: Đăng nhập thành công, chuyển đến Dashboard; tên người dùng hiển thị đúng theo nhân viên đã gán cho tài khoản. | E27: TC_ADM_CREATE_007 | F27: Pass | G27: 46322 | H27: High | I27: Positive
A28: TC_ADM_CREATE_010 | B28: Kiểm tra không đăng nhập được bằng tài khoản có Status "Disabled" | C28: 1. Đăng xuất. 2. Đăng nhập với Username "g10tv5_off01", Password "Test@12345". | D28: Đăng nhập thất bại, hiển thị thông báo lỗi "Account disabled"; người dùng không vào được hệ thống. | E28: TC_ADM_CREATE_008 | F28: Pass | G28: 46322 | H28: High | I28: Negative
B29: 1.3. Trường Employee Name
B30: Gợi ý nhân viên
A31: TC_ADM_CREATE_011 | B31: Kiểm tra hiển thị gợi ý (autocomplete) khi nhập Employee Name | C31: 1. Click ô Employee Name, nhập 1-2 ký tự (VD: "a"). 2. Quan sát danh sách gợi ý. 3. Chọn một nhân viên trong danh sách. | D31: Hiển thị danh sách nhân viên khớp từ khóa; khi chọn, họ tên đầy đủ của nhân viên được điền vào ô Employee Name. | E31: TC_ADM_CREATE_002 | F31: Pass | G31: 46322 | H31: Medium | I31: Positive
B32: Employee không hợp lệ
A33: TC_ADM_CREATE_012 | B33: Kiểm tra nhập Employee Name không tồn tại trong hệ thống | C33: 1. Nhập Employee Name "zzzxxx999" (không chọn từ gợi ý). 2. Điền các trường còn lại hợp lệ. 3. Click [Save]. | D33: Danh sách gợi ý hiển thị "No Records Found"; ô Employee Name báo lỗi "Invalid"; tài khoản không được tạo. | E33: TC_ADM_CREATE_002 | F33: Pass | G33: 46322 | H33: High | I33: Negative
A34: TC_ADM_CREATE_013 | B34: Kiểm tra tạo tài khoản cho nhân viên đã có tài khoản hệ thống | C34: 1. Chọn Employee Name là nhân viên đã được gán cho tài khoản "g10tv5_ess01". 2. Điền các trường còn lại hợp lệ với Username mới "g10tv5_dupemp". 3. Click [Save]. | D34: Hệ thống không cho tạo; hiển thị lỗi tại ô Employee Name (nhân viên đã có tài khoản, VD: "Already exists"); không phát sinh bản ghi mới trong danh sách. | E34: TC_ADM_CREATE_007 | F34: Pass | G34: 46322 | H34: Medium | I34: Negative
B35: 1.4. Kiểm tra trường bắt buộc
B36: Bỏ trống dữ liệu
A37: TC_ADM_CREATE_014 | B37: Kiểm tra bấm [Save] khi bỏ trống toàn bộ các trường | C37: 1. Mở form Add User, không nhập dữ liệu. 2. Click [Save]. | D37: Hệ thống không lưu dữ liệu; hiển thị thông báo "Required" màu đỏ dưới 6 trường: User Role, Employee Name, Status, Username, Password, Confirm Password; vẫn ở trang Add User. | E37: TC_ADM_CREATE_002 | F37: Pass | G37: 46322 | H37: High | I37: Negative
A38: TC_ADM_CREATE_015 | B38: Kiểm tra bấm [Save] khi chỉ bỏ trống Password và Confirm Password | C38: 1. Chọn User Role "ESS", chọn Employee Name, chọn Status "Enabled", nhập Username "g10tv5_nopass". 2. Để trống Password và Confirm Password. 3. Click [Save]. | D38: Không lưu dữ liệu; hiển thị "Required" tại ô Password và Confirm Password; các trường đã nhập được giữ nguyên. | E38: TC_ADM_CREATE_002 | F38: Pass | G38: 46322 | H38: High | I38: Negative
B39: 1.5. Kiểm tra trường Username
B40: Trùng lặp Username
A41: TC_ADM_CREATE_016 | B41: Kiểm tra tạo tài khoản với Username đã tồn tại | C41: 1. Nhập Username "Admin" (đã tồn tại). 2. Điền các trường còn lại hợp lệ. 3. Click [Save]. | D41: Ô Username hiển thị lỗi "Username already exists"; tài khoản không được tạo. | E41: TC_ADM_CREATE_002 | F41: Pass | G41: 46322 | H41: High | I41: Negative
A42: TC_ADM_CREATE_017 | B42: Kiểm tra Username trùng nhưng khác chữ hoa/thường | C42: 1. Nhập Username "ADMIN". 2. Điền các trường còn lại hợp lệ. 3. Click [Save]. | D42: Hệ thống xem là Username đã tồn tại (không phân biệt hoa/thường), hiển thị "Username already exists"; tài khoản không được tạo. | E42: TC_ADM_CREATE_002 | F42: Pass | G42: 46322 | H42: Medium | I42: Edge case
B43: Giá trị biên độ dài Username
...

Sheet Tìm kiếm và chỉnh sửa tài khoản
A2: Module Code | B2: Admin – Quản trị hệ thống | I2: Pass
A3: Test requirement | B3: F14. Tìm kiếm và chỉnh sửa tài khoản | I3: Fail
A4: Req ID | B4: REQ-ADM-01 | I4: Pending
A5: Tester | B5: Ngô Thanh Vy | I5: Untested
A6: Pass | B6: Fail | C6: Untested | D6: Pending | E6: N/A | F6: Number of Test cases | I6: N/A
A7: =COUNTIF($F$14:$F$65,"Pass") -> 27 | B7: =COUNTIF($F$14:$F$65,"Fail") -> 2 | C7: =COUNTIF($F$14:$F$65,"Untested") -> 0 | D7: =COUNTIF($F$14:$F$65,"Pending") -> 0 | E7: =COUNTIF($F$14:$F$65,"N/A") -> 0 | F7: =COUNTIF($A$14:$A$65,"TC_*") -> 29 | I7: Cancel
A9: Test Case ID | B9: Test Case Description | C9: Test Case Procedure | D9: Expected Output | E9: Inter-test case Dependence | F9: Result | G9: Test date | H9: Priority | I9: Note
A10: Chrome
B12: 2.1. Màn hình System Users
B13: Hiển thị màn hình
A14: TC_ADM_SEARCH_001 | B14: Kiểm tra bố cục khu vực tìm kiếm và bảng kết quả | C14: 1. Đăng nhập Admin, vào Admin > User Management > Users. 2. Quan sát khu vực tìm kiếm và bảng kết quả. | D14: Khu vực tìm kiếm gồm: Username, User Role (-- Select --), Employee Name (Type for hints...), Status (-- Select --) và nút [Reset], [Search]. Bảng kết quả gồm các cột: Username, User Role, Employee Name, Status, Actions; có nút [+ Add] và dòng "(n) Records Found". | E14: TC_ADM_CREATE_001 | F14: Pass | G14: 46322 | H14: Medium | I14: Positive
A15: TC_ADM_SEARCH_002 | B15: Kiểm tra danh sách mặc định khi chưa nhập điều kiện lọc | C15: Mở trang System Users và quan sát danh sách. | D15: Hiển thị toàn bộ tài khoản hệ thống (trong đó có "Admin"); số lượng khớp với dòng "(n) Records Found"; dữ liệu được phân trang khi vượt quá số bản ghi mỗi trang. | E15: TC_ADM_SEARCH_001 | F15: Pass | G15: 46322 | H15: Medium | I15: Positive
B16: 2.2. Tìm kiếm theo từng tiêu chí
B17: Tìm theo Username
A18: TC_ADM_SEARCH_003 | B18: Kiểm tra tìm kiếm theo Username chính xác | C18: 1. Nhập Username "g10tv5_admin01". 2. Click [Search]. | D18: Hiển thị "(1) Record Found" với đúng tài khoản "g10tv5_admin01" (User Role "Admin", Status "Enabled", đúng Employee Name). | E18: TC_ADM_SEARCH_001 TC_ADM_CREATE_006 | F18: Pass | G18: 46322 | H18: High | I18: Positive
A19: TC_ADM_SEARCH_004 | B19: Kiểm tra tìm kiếm theo một phần Username (không phân biệt hoa/thường) | C19: 1. Nhập Username "G10TV5" (viết hoa). 2. Click [Search]. | D19: Hiển thị tất cả tài khoản có Username chứa "g10tv5" (không phân biệt hoa/thường), bao gồm: g10tv5_admin01, g10tv5_ess01, g10tv5_off01. | E19: TC_ADM_SEARCH_001 TC_ADM_CREATE_008 | F19: Pass | G19: 46322 | H19: Medium | I19: Positive
B20: Tìm theo User Role
A21: TC_ADM_SEARCH_005 | B21: Kiểm tra lọc theo User Role "Admin" | C21: 1. Chọn User Role "Admin". 2. Click [Search]. | D21: Chỉ hiển thị các tài khoản có User Role "Admin" (có "g10tv5_admin01"); số lượng khớp "(n) Records Found". | E21: TC_ADM_SEARCH_001 | F21: Pass | G21: 46322 | H21: High | I21: Positive
A22: TC_ADM_SEARCH_006 | B22: Kiểm tra lọc theo User Role "ESS" | C22: 1. Chọn User Role "ESS". 2. Click [Search]. | D22: Chỉ hiển thị các tài khoản có User Role "ESS"; không xuất hiện tài khoản Admin. | E22: TC_ADM_SEARCH_001 | F22: Pass | G22: 46322 | H22: Medium | I22: Positive
B23: Tìm theo Employee Name
A24: TC_ADM_SEARCH_007 | B24: Kiểm tra tìm kiếm theo Employee Name chọn từ gợi ý | C24: 1. Tại ô Employee Name, nhập tên nhân viên đã được gán cho "g10tv5_ess01" và chọn từ danh sách gợi ý. 2. Click [Search]. | D24: Hiển thị đúng tài khoản gắn với nhân viên đã chọn (g10tv5_ess01); không hiển thị tài khoản của nhân viên khác. | E24: TC_ADM_SEARCH_001 TC_ADM_CREATE_007 | F24: Pass | G24: 46322 | H24: Medium | I24: Positive
B25: Tìm theo Status
A26: TC_ADM_SEARCH_008 | B26: Kiểm tra lọc theo Status "Enabled" | C26: 1. Chọn Status "Enabled". 2. Click [Search]. | D26: Chỉ hiển thị các tài khoản có Status "Enabled". | E26: TC_ADM_SEARCH_001 | F26: Pass | G26: 46322 | H26: Medium | I26: Positive
A27: TC_ADM_SEARCH_009 | B27: Kiểm tra lọc theo Status "Disabled" | C27: 1. Chọn Status "Disabled". 2. Click [Search]. | D27: Chỉ hiển thị các tài khoản có Status "Disabled" (có "g10tv5_off01"). | E27: TC_ADM_SEARCH_001 TC_ADM_CREATE_008 | F27: Pass | G27: 46322 | H27: Medium | I27: Positive
B28: Kết hợp nhiều điều kiện
A29: TC_ADM_SEARCH_010 | B29: Kiểm tra tìm kiếm kết hợp Username, User Role và Status | C29: 1. Nhập Username "g10tv5". 2. Chọn User Role "ESS", Status "Disabled". 3. Click [Search]. | D29: Chỉ hiển thị các tài khoản thỏa đồng thời cả 3 điều kiện (VD: "g10tv5_off01"); các tài khoản khác không xuất hiện. | E29: TC_ADM_SEARCH_003 TC_ADM_CREATE_008 | F29: Pass | G29: 46322 | H29: High | I29: Positive
B30: 2.3. Tìm kiếm không có kết quả & dữ liệu không hợp lệ
B31: Không có kết quả
A32: TC_ADM_SEARCH_011 | B32: Kiểm tra tìm kiếm Username không tồn tại | C32: 1. Nhập Username "zzz_not_exist_999". 2. Click [Search]. | D32: Hiển thị thông báo "No Records Found"; bảng kết quả không có dòng dữ liệu nào. | E32: TC_ADM_SEARCH_001 | F32: Pass | G32: 46322 | H32: High | I32: Negative
B33: Dữ liệu không hợp lệ
A34: TC_ADM_SEARCH_012 | B34: Kiểm tra tìm kiếm với chuỗi SQL Injection trong ô Username | C34: 1. Nhập Username "' OR '1'='1". 2. Click [Search]. | D34: Hệ thống xử lý như chuỗi thường: hiển thị "No Records Found"; không trả về toàn bộ danh sách, không lộ dữ liệu và không phát sinh lỗi hệ thống. | E34: TC_ADM_SEARCH_001 | F34: Pass | G34: 46322 | H34: Medium | I34: Negative
A35: TC_ADM_SEARCH_013 | B35: Kiểm tra nhập Employee Name tự do (không chọn từ gợi ý) rồi tìm kiếm | C35: 1. Nhập "abc xyz" vào ô Employee Name (không chọn gợi ý). 2. Click [Search]. | D35: Ô Employee Name hiển thị lỗi "Invalid"; hệ thống không thực hiện tìm kiếm. | E35: TC_ADM_SEARCH_001 | F35: Pass | G35: 46322 | H35: Medium | I35: Negative
B36: 2.4. Đặt lại bộ lọc & Sắp xếp
B37: Đặt lại bộ lọc
A38: TC_ADM_SEARCH_014 | B38: Kiểm tra nút [Reset] sau khi đã tìm kiếm | C38: 1. Thực hiện tìm kiếm với Username "g10tv5" và Status "Disabled". 2. Click [Reset]. | D38: Tất cả điều kiện lọc được đưa về mặc định (ô trống / "-- Select --"); danh sách tải lại đầy đủ tài khoản; số lượng "(n) Records Found" cập nhật tương ứng. | E38: TC_ADM_SEARCH_010 | F38: Pass | G38: 46322 | H38: High | I38: Positive
B39: Sắp xếp danh sách
A40: TC_ADM_SEARCH_015 | B40: Kiểm tra sắp xếp danh sách theo Username tăng dần và giảm dần | C40: 1. Click biểu tượng sắp xếp cạnh tiêu đề cột "Username". 2. Chọn "Ascending", quan sát danh sách. 3. Chọn lại "Descending", quan sát danh sách. | D40: Danh sách sắp xếp theo thứ tự bảng chữ cái tăng dần khi chọn Ascending và giảm dần khi chọn Descending; dữ liệu các cột khác đi cùng đúng dòng. | E40: TC_ADM_SEARCH_002 | F40: Pass | G40: 46322 | H40: Medium | I40: Positive
B41: 2.5. Mở form chỉnh sửa
B42: Mở form Edit User
A43: TC_ADM_SEARCH_016 | B43: Kiểm tra click icon [Edit] mở form Edit User với dữ liệu hiện tại | C43: 1. Tìm kiếm Username "g10tv5_ess01". 2. Click icon bút chì (Edit) ở cột Actions. | D43: Hiển thị trang Edit User; các trường User Role "ESS", Employee Name, Status "Enabled", Username "g10tv5_ess01" được điền sẵn đúng dữ liệu hiện tại; phần mật khẩu không bắt buộc (có tùy chọn đổi mật khẩu). | E43: TC_ADM_SEARCH_003 TC_ADM_CREATE_007 | F43: Pass | G43: 46322 | H43: High | I43: Positive
...

Sheet Quản lý danh mục hệ thống
A2: Module Code | B2: Admin – Quản trị hệ thống | I2: Pass
A3: Test requirement | B3: F15. Quản lý danh mục hệ thống | I3: Fail
A4: Req ID | B4: REQ-ADM-01 | I4: Pending
A5: Tester | B5: Ngô Thanh Vy | I5: Untested
A6: Pass | B6: Fail | C6: Untested | D6: Pending | E6: N/A | F6: Number of Test cases | I6: N/A
A7: =COUNTIF($F$14:$F$55,"Pass") -> 26 | B7: =COUNTIF($F$14:$F$55,"Fail") -> 1 | C7: =COUNTIF($F$14:$F$55,"Untested") -> 0 | D7: =COUNTIF($F$14:$F$55,"Pending") -> 0 | E7: =COUNTIF($F$14:$F$55,"N/A") -> 0 | F7: =COUNTIF($A$14:$A$55,"TC_*") -> 27 | I7: Cancel
A9: Test Case ID | B9: Test Case Description | C9: Test Case Procedure | D9: Expected Output | E9: Inter-test case Dependence | F9: Result | G9: Test date | H9: Priority | I9: Note
A10: Chrome
B12: 3.1. Job Titles - Điều hướng & Hiển thị
B13: Điều hướng
A14: TC_ADM_CATALOG_001 | B14: Kiểm tra truy cập danh mục Job Titles từ menu Admin | C14: 1. Đăng nhập bằng tài khoản Admin. 2. Click menu Admin > Job > Job Titles. | D14: Hiển thị trang Job Titles gồm nút [+ Add], bảng với các cột Job Titles, Job Description, Actions và dòng "(n) Records Found". | E14: TC_ADM_CREATE_001 | F14: Pass | G14: 46322 | H14: High | I14: Positive
B15: Hiển thị form
A16: TC_ADM_CATALOG_002 | B16: Kiểm tra bố cục form Add Job Title | C16: 1. Tại trang Job Titles, click [+ Add]. 2. Quan sát form. | D16: Form "Add Job Title" gồm: Job Title*, Job Description, Job Specification (nút Browse, ghi chú dung lượng tối đa 1MB), Note; có nút [Cancel] và [Save]. | E16: TC_ADM_CATALOG_001 | F16: Pass | G16: 46322 | H16: Medium | I16: Positive
B17: 3.2. Job Titles - Thêm mới
B18: Thêm mới hợp lệ
A19: TC_ADM_CATALOG_003 | B19: Kiểm tra thêm Job Title chỉ với trường bắt buộc | C19: 1. Click [+ Add]. 2. Nhập Job Title "G10TV5 QA Intern". 3. Click [Save]. | D19: Hiển thị "Successfully Saved"; Job Title "G10TV5 QA Intern" xuất hiện trong danh sách. | E19: TC_ADM_CATALOG_002 | F19: Pass | G19: 46322 | H19: High | I19: Positive
A20: TC_ADM_CATALOG_004 | B20: Kiểm tra thêm Job Title với đầy đủ thông tin Title, Description và Note | C20: 1. Click [+ Add]. 2. Nhập Job Title "G10TV5 Test Analyst". 3. Nhập Job Description "Thực hiện kiểm thử chức năng module Admin". 4. Nhập Note "Dữ liệu kiểm thử Group10". 5. Click [Save]. | D20: Hiển thị "Successfully Saved"; Job Title mới xuất hiện trong danh sách, cột Job Description hiển thị đúng nội dung đã nhập (chữ có dấu hiển thị chính xác). | E20: TC_ADM_CATALOG_002 | F20: Pass | G20: 46322 | H20: Medium | I20: Positive
A21: TC_ADM_CATALOG_005 | B21: Kiểm tra thêm Job Title kèm Job Specification hợp lệ (PDF dưới 1MB) | C21: 1. Click [+ Add], nhập Job Title "G10TV5 Spec Test". 2. Tại Job Specification, click [Browse] và chọn tệp PDF dung lượng dưới 1MB. 3. Click [Save]. | D21: Hiển thị "Successfully Saved"; Job Title được tạo kèm tệp đính kèm; tại danh sách có biểu tượng tải xuống và tệp tải về mở được. | E21: TC_ADM_CATALOG_002 | F21: Pass | G21: 46322 | H21: Medium | I21: Positive
B22: Dữ liệu không hợp lệ
A23: TC_ADM_CATALOG_006 | B23: Kiểm tra bấm [Save] khi bỏ trống Job Title | C23: 1. Click [+ Add]. 2. Để trống Job Title. 3. Click [Save]. | D23: Ô Job Title hiển thị lỗi "Required"; dữ liệu không được lưu. | E23: TC_ADM_CATALOG_002 | F23: Pass | G23: 46322 | H23: High | I23: Negative
A24: TC_ADM_CATALOG_007 | B24: Kiểm tra thêm Job Title trùng tên đã tồn tại | C24: 1. Click [+ Add]. 2. Nhập Job Title "G10TV5 QA Intern" (đã tạo). 3. Click [Save]. | D24: Ô Job Title hiển thị lỗi "Already exists"; không tạo thêm bản ghi. | E24: TC_ADM_CATALOG_003 | F24: Pass | G24: 46322 | H24: High | I24: Negative
A25: TC_ADM_CATALOG_008 | B25: Kiểm tra Job Title có đúng 100 ký tự (giá trị tối đa) | C25: 1. Click [+ Add]. 2. Nhập Job Title gồm 100 ký tự (VD: "G10TV5 " + 93 ký tự "A"). 3. Click [Save]. | D25: Hiển thị "Successfully Saved"; Job Title 100 ký tự được lưu và hiển thị trong danh sách. | E25: TC_ADM_CATALOG_002 | F25: Pass | G25: 46322 | H25: Medium | I25: Edge case
A26: TC_ADM_CATALOG_009 | B26: Kiểm tra Job Title có 101 ký tự (vượt quá giá trị tối đa) | C26: 1. Click [+ Add]. 2. Nhập Job Title gồm 101 ký tự (VD: "G10TV5 " + 94 ký tự "A"). 3. Click [Save]. | D26: Ô Job Title hiển thị lỗi "Should not exceed 100 characters"; dữ liệu không được lưu. | E26: TC_ADM_CATALOG_002 | F26: Pass | G26: 46322 | H26: Medium | I26: Edge case
A27: TC_ADM_CATALOG_010 | B27: Kiểm tra Job Description có 401 ký tự (vượt quá giá trị tối đa) | C27: 1. Click [+ Add], nhập Job Title "G10TV5 Long Desc". 2. Nhập Job Description gồm 401 ký tự. 3. Click [Save]. | D27: Ô Job Description hiển thị lỗi "Should not exceed 400 characters"; dữ liệu không được lưu. | E27: TC_ADM_CATALOG_002 | F27: Pass | G27: 46322 | H27: Low | I27: Edge case
A28: TC_ADM_CATALOG_011 | B28: Kiểm tra tải lên Job Specification vượt quá 1MB | C28: 1. Click [+ Add], nhập Job Title "G10TV5 Big File". 2. Chọn tệp PDF có dung lượng lớn hơn 1MB tại Job Specification. 3. Click [Save]. | D28: Hệ thống báo lỗi dung lượng tệp vượt quá giới hạn (VD: "Attachment Size Exceeded"); dữ liệu không được lưu. | E28: TC_ADM_CATALOG_002 | F28: Pass | G28: 46322 | H28: Medium | I28: Negative
A29: TC_ADM_CATALOG_012 | B29: Kiểm tra tải lên Job Specification sai định dạng tệp (.exe/.jpg) | C29: 1. Click [+ Add], nhập Job Title "G10TV5 Bad File". 2. Chọn tệp có định dạng không được hỗ trợ (VD: .exe hoặc .jpg). 3. Click [Save]. | D29: Hệ thống báo lỗi định dạng tệp không được phép (VD: "File type not allowed"); dữ liệu không được lưu. | E29: TC_ADM_CATALOG_002 | F29: Pass | G29: 46322 | H29: Medium | I29: Negative
B30: Hủy thao tác
A31: TC_ADM_CATALOG_013 | B31: Kiểm tra nút [Cancel] khi thêm Job Title | C31: 1. Click [+ Add], nhập Job Title "G10TV5 Cancel". 2. Click [Cancel]. | D31: Hệ thống quay về trang Job Titles; "G10TV5 Cancel" không xuất hiện trong danh sách. | E31: TC_ADM_CATALOG_002 | F31: Pass | G31: 46322 | H31: Low | I31: Positive
B32: 3.3. Job Titles - Sửa & Xóa
B33: Chỉnh sửa Job Title
A34: TC_ADM_CATALOG_014 | B34: Kiểm tra chỉnh sửa tên Job Title hợp lệ | C34: 1. Tại dòng "G10TV5 Test Analyst", click icon bút chì (Edit). 2. Đổi Job Title thành "G10TV5 Test Analyst Sr". 3. Click [Save]. | D34: Hiển thị "Successfully Updated"; danh sách hiển thị tên mới, không còn tên cũ. | E34: TC_ADM_CATALOG_004 | F34: Pass | G34: 46322 | H34: High | I34: Positive
A35: TC_ADM_CATALOG_015 | B35: Kiểm tra đổi tên Job Title thành tên đã tồn tại | C35: 1. Mở Edit của "G10TV5 Test Analyst Sr". 2. Đổi Job Title thành "G10TV5 QA Intern". 3. Click [Save]. | D35: Ô Job Title hiển thị lỗi "Already exists"; dữ liệu không được cập nhật. | E35: TC_ADM_CATALOG_014 TC_ADM_CATALOG_003 | F35: Pass | G35: 46322 | H35: Medium | I35: Negative
B36: Xóa Job Title
A37: TC_ADM_CATALOG_016 | B37: Kiểm tra xóa Job Title kiểm thử có xác nhận | C37: 1. Tại dòng "G10TV5 QA Intern", click icon thùng rác (Delete). 2. Tại hộp thoại xác nhận, click [Yes, Delete]. | D37: Hiển thị "Successfully Deleted"; Job Title biến mất khỏi danh sách. | E37: TC_ADM_CATALOG_003 | F37: Pass | G37: 46322 | H37: High | I37: Positive
A38: TC_ADM_CATALOG_017 | B38: Kiểm tra xóa Job Title đang được gán cho nhân viên | C38: 1. Chọn một Job Title đang được gán cho nhân viên (VD: Job Title có sẵn trên hệ thống demo). 2. Click icon thùng rác (Delete) và xác nhận. | D38: Hệ thống không xóa; hiển thị thông báo bản ghi đang được sử dụng (VD: "Cannot be deleted"); dữ liệu giữ nguyên trong danh sách. | E38: TC_ADM_CATALOG_001 | F38: Pass | G38: 46322 | H38: Medium | I38: Negative
B39: 3.4. Employment Status
B40: Thêm mới Employment Status
A41: TC_ADM_CATALOG_018 | B41: Kiểm tra thêm Employment Status hợp lệ | C41: 1. Click menu Admin > Job > Employment Status. 2. Click [+ Add], nhập Name "G10TV5 Contract". 3. Click [Save]. | D41: Hiển thị "Successfully Saved"; "G10TV5 Contract" xuất hiện trong danh sách Employment Status. | E41: TC_ADM_CATALOG_001 | F41: Pass | G41: 46322 | H41: High | I41: Positive
A42: TC_ADM_CATALOG_019 | B42: Kiểm tra thêm Employment Status khi bỏ trống Name | C42: 1. Click [+ Add]. 2. Để trống Name. 3. Click [Save]. | D42: Ô Name hiển thị lỗi "Required"; dữ liệu không được lưu. | E42: TC_ADM_CATALOG_001 | F42: Pass | G42: 46322 | H42: Medium | I42: Negative
A43: TC_ADM_CATALOG_020 | B43: Kiểm tra thêm Employment Status trùng tên | C43: 1. Click [+ Add]. 2. Nhập Name "G10TV5 Contract" (đã tạo). 3. Click [Save]. | D43: Ô Name hiển thị lỗi "Already exists"; không tạo thêm bản ghi. | E43: TC_ADM_CATALOG_018 | F43: Pass | G43: 46322 | H43: Medium | I43: Negative
...

Sheet Test Report 
B1: TEST REPORT
B3: Project Name | C3: OrangeHRM | E3: Creator | G3: Ngô Thanh Vy
B4: Project Code | C4: OHRM_ADM | E4: Reviewer/Approver | G4: Trần Thị Thanh Nga
B5: Document Code | C5: OHRM_ADM_TestReport_v0.1 | E5: Issue Date | G5: 46322
B6: Notes | C6: Báo cáo tổng hợp kết quả kiểm thử module Admin (TV5: F13, F14, F15). Cột Blocked lấy từ số case "Pending", cột Skipped lấy từ số case "N/A" của từng sheet.
B10: No | C10: Module code | D10: Pass | E10: Fail | F10: Untested | G10: Blocked | H10: Skipped | I10: Number of test cases
B11: 1 | C11: F13. Tạo tài khoản hệ thống | D11: ='Tạo tài khoản hệ thống'!A7 -> 29 | E11: ='Tạo tài khoản hệ thống'!B7 -> 0 | F11: ='Tạo tài khoản hệ thống'!C7 -> 0 | G11: ='Tạo tài khoản hệ thống'!D7 -> 0 | H11: ='Tạo tài khoản hệ thống'!E7 -> 0 | I11: ='Tạo tài khoản hệ thống'!F7 -> 29
B12: 2 | C12: F14. Tìm kiếm và chỉnh sửa tài khoản | D12: ='Tìm kiếm và chỉnh sửa tài khoản'!A7 -> 27 | E12: ='Tìm kiếm và chỉnh sửa tài khoản'!B7 -> 2 | F12: ='Tìm kiếm và chỉnh sửa tài khoản'!C7 -> 0 | G12: ='Tìm kiếm và chỉnh sửa tài khoản'!D7 -> 0 | H12: ='Tìm kiếm và chỉnh sửa tài khoản'!E7 -> 0 | I12: ='Tìm kiếm và chỉnh sửa tài khoản'!F7 -> 29
B13: 3 | C13: F15. Quản lý danh mục hệ thống | D13: ='Quản lý danh mục hệ thống'!A7 -> 26 | E13: ='Quản lý danh mục hệ thống'!B7 -> 1 | F13: ='Quản lý danh mục hệ thống'!C7 -> 0 | G13: ='Quản lý danh mục hệ thống'!D7 -> 0 | H13: ='Quản lý danh mục hệ thống'!E7 -> 0 | I13: ='Quản lý danh mục hệ thống'!F7 -> 27
C15: Sub total | D15: =SUM(D9:D14) -> 82 | E15: =SUM(E9:E14) -> 3 | F15: =SUM(F9:F14) -> 0 | G15: =SUM(G9:G14) -> 0 | H15: =SUM(H9:H14) -> 0 | I15: =SUM(I9:I14) -> 85
C17: Test coverage | E17: =IFERROR((D15+E15)*100/(I15-H15-G15),0) -> 100 | F17: %
C18: Test successful coverage | E18: =IFERROR(D15*100/(D15+E15),0) -> 96.470588 | F18: %
